Workbook

Sheet 2017 
A1: 项目经营管理台账（2017年）（电子）
A2: 序号 | B2: 项目信息 | E2: 经营信息 | J2: 概算信息（估算） | M2: 审计信息 | P2: 甲方支付信息 | W2: 公司收支信息 | AF2: 备注
B3: 项目名称 | C3: 项目概况 | D3: 项目编号 | E3: 甲方单位 | F3: 联系人 | G3: 联系方式 | H3: 经营 负责人 | I3: 经营 参与人 | J3: 设计费（元） | K3: 勘察费（元） | L3: 可研费（元） | M3: 设计费（元） | N3: 勘察费（元） | O3: 可研费（元） | P3: 合同/补充协议额（元） | T3: 应支额（元） | W3: 应收额（元） | X3: 收款信息 | Z3: 支付信息 | AE3: 公司结余 （元）
P4: 设计费（元） | Q4: 勘察费（元） | R4: 可研费（元） | S4: 补充协议额（元） | U4: 支付金额（元） | V4: 未收金额（元） | X4: 实收金额（元） | Y4: 未收金额（元） | Z4: 单位 （个人） | AA4: 内容 | AB4: 金额（元） | AC4: 经营奖金（元） | AD4: 生产奖金（元）
A5: 1 | B5: 房山区108国道大修工程（峡峪口桥-十霞路）K73+900-K104+330 | C5: 二级路、30km | D5: HNJH2017-001 | E5: 房山公路局 | F5: 白秀龙 | G5: 13811745176 | H5: 杨建东 | I5: 王新星 | J5: 744841 | K5: 304570 | L5: 0 | M5: =INT(J5*0.99) -> 737392 | N5: =INT(K5*0.99) -> 301524 | O5: =INT(L5*0.99) -> 0 | P5: =M5 -> 737392 | Q5: =N5 -> 301524 | R5: =O5 -> 0 | S5: =P5+Q5+R5 -> 1038916 | T5: =S5 -> 1038916 | U5: 311674 | V5: =T5-U5-U6-U7 -> 0 | W5: =S5*0.8 -> 831132.8 | X5: =U5*0.8 -> 249339.2 | Y5: =W5-X5-X6-X7 -> 0 | Z5: 刘素良 | AA5: 测量 | AB5: 76075 | AC5: =77918.7+22841.87+28018.79+16668.8 -> 145448.16 | AD5: =44243.52+13273.06+15902.12+9464.82 -> 82883.52 | AE5: =W5-AB5-AB6-AB7-AC5-AD5 -> 481874.12 | AG5: =AC5/T5 -> 0.13999992 | AH5: =AD5/W5 -> 0.099723558
U6: 415566 | X6: =U6*0.8 -> 332452.8 | AA6: 取芯 | AB6: =15*150 -> 2250
U7: 311676 | X7: =U7*0.8 -> 249340.8 | Z7: 瑞通十九处 | AA7: 路况 | AB7: 42602
A8: 2 | B8: 房山区108国道大修工程（涞宝路-市界）K120+850-139+450 | C8: 二级路、15km | D8: HNJH2017-002 | E8: 房山公路局 | F8: 白秀龙 | G8: 13811745176 | H8: 杨建东 | I8: 王新星 | J8: 632486 | K8: 187280 | L8: 0 | M8: 624894 | N8: 185407 | O8: =INT(L8*0.99) -> 0 | P8: =M8 -> 624894 | Q8: =N8 -> 185407 | R8: =O8 -> 0 | S8: =P8+Q8+R8 -> 810301 | T8: =S8 -> 810301 | U8: 243470 | V8: =S8-U8-U9-U10 -> 0 | W8: =S8*0.8 -> 648240.8 | X8: =U8*0.8 -> 194776 | Y8: =W8-X8-X9-X10 -> 0 | Z8: 刘素梁 | AA8: 测绘 | AB8: 46500 | AC8: =60867.6+3233.13+49518.75 -> 113619.48 | AD8: =37569.66+2003.72+30567.13 -> 70140.51 | AE8: =W8-AB8-AB9-AB10-AC8-AD8 -> 385820.81 | AG8: =AC8/T8 -> 0.14021886 | AH8: =AD8/W8 -> 0.10820132
U9: 324627 | X9: =U9*0.8 -> 259701.6 | Z9: 刘素梁 | AA9: 取芯 | AB9: =16*150 -> 2400
U10: 242204 | X10: =U10*0.8 -> 193763.2 | Z10: 瑞通十九处 | AA10: 路况 | AB10: 29760
A11: 4 | B11: 房山区良三路大修工程（K4+500-K8+500) | C11: 一级路、3.956km | D11: HNJH2017-004 | E11: 房山公路局 | F11: 白秀龙 | G11: 13811745176 | H11: 王新星 | I11: 王新星 | J11: 552573.9 | K11: 59340 | L11: 0 | M11: 552573.9 | N11: 59340 | O11: =INT(L11*0.99) -> 0 | P11: =M11 -> 552573.9 | Q11: =N11 -> 59340 | R11: =O11 -> 0 | S11: =P11+Q11+R11 -> 611913.9 | T11: =S11 -> 611913.9 | U11: 183573.9 | V11: =S11-U11-U12-U13 -> 0 | W11: =S11*0.8 -> 489531.12 | X11: =U11*0.8 -> 146859.12 | Y11: =W11-X11-X12-X13 -> 0 | Z11: 刘素良 | AA11: 测量 | AB11: =50000-AB12 -> 47300 | AC11: =45893.48+39774.31 -> 85667.79 | AD11: =33154.38+28733.76 -> 61888.14 | AE11: =W11-AB11-AB12-AB13-AC11-AD11 -> 277655.19 | AG11: =AC11/T11 -> 0.13999975 | AH11: =AD11/W11 -> 0.1264233
U12: 244765 | X12: =U12*0.8 -> 195812 | Z12: 刘素良 | AA12: 取芯 | AB12: =18*150 -> 2700
U13: 183575 | X13: =U13*0.8 -> 146860 | Z13: 瑞通十九处 | AA13: 路况 | AB13: 14320
A14: 6 | B14: 延庆区滦赤路大修工程（K108+890-K129+000) | C14: 三级路、20.11km | D14: HNJH2017-006 | E14: 延庆公路局 | F14: 吴颖 | G14: 13488805779 | H14: 杨建东 | I14: 王新星 | J14: 449664 | K14: 213100 | L14: 0 | M14: 445167 | N14: 210969 | O14: 0 | P14: =M14 -> 445167 | Q14: =N14 -> 210969 | R14: =O14 -> 0 | S14: =P14+Q14+R14 -> 656136 | T14: =S14 -> 656136 | U14: 411294 | V14: =S14-U14-U15-U16 -> 0 | W14: =S14*0.8 -> 524908.8 | X14: =U14*0.8 -> 329035.2 | Y14: =W14-X14-X15-X16 -> 0 | Z14: 刘素良 | AA14: 测量 | AB14: =20.11*2500 -> 50275 | AC14: =12465.8+49210.2+42488.05+18159.75+10450 -> 132773.8 | AD14: =6980.85+27557.71+23113.5+9793.67+2840.18 -> 70285.91 | AE14: =W14-AB14-AB15-AB16-AC14-AD14 -> 253086.09 | AG14: =AC14/T14 -> 0.20235713 | AH14: =AD14/W14 -> 0.13390118
U15: 200325 | X15: =U15*0.8 -> 160260 | AA15: 取芯 | AB15: =16*150 -> 2400
U16: 44517 | X16: =U16*0.8 -> 35613.6 | Z16: 瑞通十九处 | AA16: 路况 | AB16: =20.11*800 -> 16088
A17: 7 | B17: 2018年通州区普通公路养护工程勘察设计-2标，通州区漷马路大修工程（K9+480-K21+000)，转中修漷马路（K10+000-K16+000）中修工程 | C17: 二、三级路、11.52km(方案） | D17: HNJH2017-007 | E17: 通州公路局 | F17: 张伟 | G17: 13439987630 | H17: 王新星 | I17: 王新星 | J17: 623024 | K17: 94960 | L17: 0 | M17: 199017 | N17: 48000 | O17: 0 | P17: =M17 -> 199017 | Q17: =N17 -> 48000 | R17: =O17 -> 0 | S17: =P17+Q17+R17 -> 247017 | T17: =S17 -> 247017 | U17: 247017 | V17: =T17-U17 -> 0 | W17: =S17*0.8 -> 197613.6 | X17: =U17*0.8 -> 197613.6 | Y17: =W17-X17 -> 0 | Z17: 刘素良 | AA17: 测量 | AB17: =6*2500 -> 15000 | AC17: =61754.25 -> 61754.25 | AD17: =31842.72 -> 31842.72 | AE17: =W17-AB17-AB18-AB19-AC17-AD17 -> 78000.63 | AG17: =AC17/T17 -> 0.25 | AH17: =AD17/W17 -> 0.16113628
AA18: 取芯 | AB18: =12*150 -> 1800
Z19: 瑞通十九处 | AA19: 路况 | AB19: =5.52*800+6*800 -> 9216
A20: 8 | B20: 2018年通州区普通公路养护工程勘察设计-2标，通州区觅西路大修工程（K0+000-K10+000) | C20: 二级路、10.54km | D20: HNJH2017-008 | E20: 通州公路局 | F20: 张伟 | G20: 13439987630 | H20: 王新星 | I20: 王新星 | J20: 783827 | K20: 105400 | L20: 0 | M20: 775989 | N20: 104346 | O20: 0 | P20: =M20 -> 775989 | Q20: =N20 -> 104346 | R20: =O20 -> 0 | S20: =P20+Q20+R20 -> 880335 | T20: =S20 -> 880335 | U20: 792301.5 | V20: =S20-U20-U21 -> 0 | W20: =S20*0.8 -> 704268 | X20: =U20*0.8 -> 633841.2 | Y20: =W20-X20-X21 -> 0 | Z20: 刘素良 | AA20: 测量 | AB20: 26350 | AC20: =66025.13+66125+4699.39+5272.94+16337.85 -> 158460.31 | AD20: =46559.34+46552+3103.96+3103.96+11521.06+15419.61 -> 126259.93 | AE20: =W20-AB20-AB21-AB22-AC20-AD20 -> 373369.76 | AG20: =AC20/T20 -> 0.18000001 | AH20: =AD20/W20 -> 0.17927824
U21: 88033.5 | X21: =U21*0.8 -> 70426.8 | AA21: 取芯 | AB21: 1950
Z22: 十九处 | AA22: 弯沉 | AB22: =10500+7378 -> 17878
A23: 9 | B23: 石桥片区、果园片区区域环境提升工程 | C23: 果园片区 | D23: HBJH2017-009 | E23: 密云园林绿化服务中心 | F23: 王辉 | G23: 13681368593 | H23: 杨建东 | I23: 杨建东 | M23: 61686.63 | N23: 0 | O23: 0 | P23: 61686.63 | Q23: 0 | R23: 0 | S23: =Q23 -> 0 | T23: =P23+Q23+R23 -> 61686.63 | U23: 61686.63 | V23: =T23-U23 -> 0 | W23: =T23*0.6 -> 37011.978 | X23: =37011.98 -> 37011.98 | Y23: =W23-X23 -> -0.002 | AC23: 17484.25 | AD23: =7063.64+12588.66-12588.66-7063.64+3738.21+6662.16 -> 10400.37 | AE23: =W23-AC23-AD23-AB23-AB24-AB25 -> 9127.358 | AG23: =AC23/T23 -> 0.28343662 | AH23: =AD23/W23 -> 0.28100011
C24: 石桥片区一
C25: 石桥片区二
C26: 石桥片区-微森公园 | M26: 275821.71 | N26: 0 | O26: 0 | P26: 275821.71 | Q26: 0 | R26: 0 | S26: =P26+Q26+R26 -> 275821.71 | T26: =S26 -> 275821.71 | U26: =T26 -> 275821.71 | V26: =T26-U26-U27 -> 0 | W26: =INT(S26*0.6) -> 165493 | X26: =W26 -> 165493 | Y26: =W26-X26 -> 0 | AD26: =41373.26 -> 41373.26 | AE26: =W26-AB26-AB27-AC26-AD26 -> 124119.74 | AG26: =AC26/T26 -> 0 | AH26: =AD26/W26 -> 0.25000006
B28: 水源路环境提升工程（二标段） | C28: 水源路4l | J28: 1424700 | K28: 108300 | L28: 0 | M28: 797775.73 | N28: 0 | O28: 0 | P28: 797775.73 | Q28: 0 | R28: 0 | S28: =P28+Q28+R28 -> 797775.73 | T28: =S28 -> 797775.73 | U28: =389093.86 -> 389093.86 | V28: =T28-U28-U29-U30 -> 0 | W28: =T28*0.75 -> 598331.8 | X28: 300000 | Y28: =W28-X28-X29-X30 -> -0.0025 | AC28: =90000+93300+29304.56 -> 212604.56 | AD28: =27500+60000+20256.34+45014.08+19536.37 -> 172306.79 | AE28: =W28-AB28-AB29-AB30-AC28-AD28 -> 213420.45 | AG28: =AC28/T28 -> 0.26649665 | AH28: =AD28/W28 -> 0.28797866
U29: 311000 | X29: 225070.4
U30: 97681.87 | X30: 73261.4
A31: 10 | B31: 物华科技综合楼项目道路开口设计工程 | C31: 开口 | D31: HXJH2017-010 | E31: 北京万华置业有限公司 | H31: 马旭 | I31: 马旭 | J31: 160000 | K31: 0 | L31: 0 | M31: 160000 | N31: 0 | O31: 0 | P31: 160000 | Q31: 0 | R31: 0 | S31: =P31+Q31+R31 -> 160000 | T31: =S31 -> 160000 | U31: =J31 -> 160000 | V31: =T31-U31 -> 0 | W31: =U31*0.81 -> 129600 | X31: 129600 | Y31: =W31-X31 -> 0 | Z31: 马旭 | AA31: 设计咨询 | AB31: =U31*0.75 -> 120000 | AE31: =W31-AB31 -> 9600 | AF31: 帮忙马旭
A32: 11 | B32: 2017年通州区年乡村公路安全生命防护工程 | C32: 9个乡镇，202条道路 | D32: HXJH2017-011 | E32: 通州公路局 | F32: 潘宝龙 | G32: 13810052975 | H32: 王新星 | I32: 王新星 | J32: 336092 | K32: 0 | L32: 0 | M32: 213641 | N32: 0 | O32: 0 | P32: 213641 | Q32: 0 | R32: 0 | S32: =P32+Q32+R32 -> 213641 | T32: =S32 -> 213641 | U32: =T32 -> 213641 | V32: =T32-U32 -> 0 | W32: =U32*0.81 -> 173049.21 | X32: 173049.21 | Y32: =W32-X32 -> 0 | AC32: 53410 | AD32: 34609.84 | AE32: =W32-AC32-AD32-AB32 -> 85029.37 | AG32: =AC32/T32 -> 0.24999883 | AH32: =AD32/W32 -> 0.19999999
A33: 12 | B33: 通州区2018年公路桥梁改建工程（张家湾镇北凉运桥） | C33: 桥长12.5米，宽10米，现浇实心板梁 | D33: HXJH2017-012 | E33: 通州公路局 | F33: 潘宝龙 | G33: 13810052975 | H33: 王新星 | I33: 王新星 | J33: 147562 | M33: 60348 | P33: =M33 -> 60348 | S33: =P33 -> 60348 | T33: =S33 -> 60348 | U33: 0 | V33: =T33-U33 -> 60348 | W33: =T33*0.8 -> 48278.4 | X33: =W33 -> 48278.4 | Y33: =W33-X33 -> 0
A34: 14 | B34: 通州区燃气管线回填道路恢复工程 | C34: 胡郎路（变更后）三级公路4.41km | D34: HXJH2017-014 | E34: 燃气基建公司 | H34: 王新星 | I34: 王新星 | J34: 199344 | K34: 35280 | L34: 0 | M34: 199344 | N34: 35280 | O34: 0 | P34: 199344 | Q34: 35280 | R34: 0 | S34: =P34+Q34 -> 234624 | T34: =S34 -> 234624 | U34: =T34 -> 234624 | V34: =T34-U34 -> 0 | W34: =U34*0.81 -> 190045.44 | X34: =W34 -> 190045.44 | Y34: =W34-X34 -> 0 | AC34: =64100.5+7839.5+69391.75+33638.75 -> 174970.5 | AD34: =5471.6+39860.4+45317.4+23567 -> 114216.4 | AE34: =W34+W35+W36+W37+W38-AC34-AD34 -> 277717.52
C35: 潞城中路（定向钻）二级公路1.57km | D35: HXJH2017-014 | E35: 燃气基建公司 | H35: 王新星 | I35: 王新星 | J35: 27243 | K35: 15700 | L35: 0 | M35: 27243 | N35: 15700 | O35: 0 | P35: 27243 | Q35: 15700 | R35: 0 | S35: =P35+Q35 -> 42943 | T35: =S35 -> 42943 | U35: =T35 -> 42943 | V35: =T35-U35 -> 0 | W35: =U35*0.81 -> 34783.83 | X35: =W35 -> 34783.83 | Y35: =W35-X35 -> 0
C36: 潞西路三级公路2.09km | D36: HXJH2017-014 | E36: 燃气基建公司 | H36: 王新星 | I36: 王新星 | J36: 117835 | K36: 16720 | L36: 0 | M36: 117835 | N36: 16720 | O36: 0 | P36: 117835 | Q36: 16720 | R36: 0 | S36: =P36+Q36 -> 134555 | T36: =S36 -> 134555 | U36: =T36 -> 134555 | V36: =T36-U36 -> 0 | W36: =U36*0.81 -> 108989.55 | X36: =W36 -> 108989.55 | Y36: =W36-X36 -> 0
C37: 张凤路（明开）二级公路3.72km，（定向钻）二级公路2.65km | D37: HXJH2017-014 | E37: 燃气基建公司 | H37: 王新星 | I37: 王新星 | J37: 199302 | K37: 57100 | L37: 0 | M37: 199302 | N37: 57100 | O37: 0 | P37: 199302 | Q37: 57100 | R37: 0 | S37: =P37+Q37 -> 256402 | T37: =S37 -> 256402 | U37: =T37 -> 256402 | V37: =T37-U37 -> 0 | W37: =U37*0.81 -> 207685.62 | X37: =W37 -> 207685.62 | Y37: =W37-X37 -> 0
C38: 漷马路三级公路0.50km | D38: HXJH2017-014 | E38: 燃气基建公司 | H38: 王新星 | I38: 王新星 | J38: 27358 | K38: 4000 | L38: 0 | M38: 27358 | N38: 4000 | O38: 0 | P38: 27358 | Q38: 4000 | R38: 0 | S38: =P38+Q38 -> 31358 | T38: =S38 -> 31358 | U38: =T38 -> 31358 | V38: =T38-U38 -> 0 | W38: =U38*0.81 -> 25399.98 | X38: =W38 -> 25399.98 | Y38: =W38-X38 -> 0
A39: 15 | B39: 2018年张家湾镇乡村公路（16条道路） | C39: 大小北关路，2.794km | D39: HNJH2017-015L01S | E39: 张湾公路站 | F39: 卢世茹 | G39: 13520175981 | H39: 王新星 | I39: 王新星 | J39: 305803.4 | K39: 35508 | L39: 0 | M39: 104954.52 | N39: 0 | O39: 0 | P39: 104954.52 | Q39: 0 | R39: 0 | S39: =P39+Q39 -> 104954.52 | T39: =S39 -> 104954.52 | U39: =T39 -> 104954.52 | V39: =T39-U39 -> 0 | W39: =U39*0.81 -> 85013.161 | X39: =W39 -> 85013.161 | Y39: =W39-X39 -> 0 | Z39: 刘素良 | AA39: 测量 | AB39: =18.864*1500 -> 28296 | AC39: =3462.8+45565.96+34434.04+100702.65 -> 184165.45 | AD39: =27702.4+27702.4+35467.25+26522.85+40648.52 -> 158043.42 | AE39: =W39+W40+W41+W42+W43+W44+W45+W46+W47+W48+W49+W50+W51+W52+W53-AB40-AB39-AC39-AD39 -> 369515.18 | AG39: =SUM(T39:T53) -> 920827.22 | AH39: =SUM(W39:W53) -> 745870.05
C40: 小北关东路，0.833km | D40: HNJH2017-015L02S | J40: 87694.56 | K40: 11867 | L40: 0 | M40: 28070.73 | N40: 0 | O40: 0 | P40: 28070.73 | Q40: 0 | R40: 0 | S40: =P40+Q40 -> 28070.73 | T40: =S40 -> 28070.73 | U40: =T40 -> 28070.73 | V40: =T40-U40 -> 0 | W40: =U40*0.81 -> 22737.291 | X40: =W40 -> 22737.291 | Y40: =W40-X40 -> 0 | AA40: 取芯 | AB40: =39*150 -> 5850
C41: 小北关北路，1.117km | D41: HNJH2017-015L03S | J41: 111553.36 | K41: 12176.26 | L41: 0 | M41: 39492.33 | N41: 0 | O41: 0 | P41: 39492.33 | Q41: 0 | R41: 0 | S41: =P41+Q41 -> 39492.33 | T41: =S41 -> 39492.33 | U41: =T41 -> 39492.33 | V41: =T41-U41 -> 0 | W41: =U41*0.81 -> 31988.787 | X41: =W41 -> 31988.787 | Y41: =W41-X41 -> 0 | AG41: =AC39/AG39 -> 0.20000001 | AH41: =AD39/AH39 -> 0.21189136
...

Sheet 2018
A1: 项目经营管理台账（2018年）（电子）
A2: 序号 | B2: 项目信息 | F2: 经营信息 | K2: 概算信息（估算） | N2: 审计信息 | Q2: 甲方支付信息 | X2: 公司收支信息 | AG2: 备注
B3: 项目名称 | C3: 承接日期 | D3: 项目概况 | E3: 项目编号 | F3: 单位 | G3: 联系人 | H3: 联系方式 | I3: 经营 负责人 | J3: 经营 参与人 | K3: 设计费（元） | L3: 勘察费（元） | M3: 可研费（元） | N3: 设计费（元） | O3: 勘察费（元） | P3: 可研费（元） | Q3: 合同/补充协议额（元） | U3: 应支额（元） | X3: 应收额（元） | Y3: 收款信息 | AA3: 支付信息 | AF3: 公司结余 （元）
Q4: 设计费（元） | R4: 勘察费（元） | S4: 可研费（元） | T4: 补充协议额（元） | V4: 支付金额（元） | W4: 未收金额（元） | Y4: 实收金额（元） | Z4: 未收金额（元） | AA4: 单位 （个人） | AB4: 内容 | AC4: 金额（元） | AD4: 经营奖金（元） | AE4: 生产奖金（元）
A5: 1 | B5: 密云望潮亭、云启、时光公园提升工程设计 | D5: 面积5.75万㎡ | E5: JNJH2018-001 | F5: 园林中心 | G5: 王辉 | H5: 13681368593 | I5: 杨建东 | J5: 杨建东 | K5: 1169900 | L5: 0 | M5: 0 | N5: 884899.04 | O5: 0 | P5: 0 | Q5: =N5 -> 884899.04 | R5: =O5 -> 0 | S5: =P5 -> 0 | T5: =Q5+R5+S5 -> 884899.04 | U5: =T5 -> 884899.04 | V5: 442400 | W5: =U5-V5-V6 -> 0 | X5: =U5*0.77 -> 681372.26 | Y5: =V5*0.77 -> 340648 | Z5: =X5-Y5-Y6 -> 0 | AA5: 刘素良 | AB5: 测绘 | AC5: =1.05*2500 -> 2625 | AD5: =132720+124647.62 -> 257367.62 | AE5: =31158.32+74942.56+70384.35 -> 176485.23 | AF5: =X5-AC5-AC6-AD5-AE5 -> 244894.41 | AH5: =AD5/U5 -> 0.29084405 | AI5: =AE5/(Q5*0.77) -> 0.2590144
V6: 442499.04 | Y6: =V6*0.77 -> 340724.26
A7: 2 | B7: 通州区通武线大修工程 | D7: 大修，K1106+773-K1111+175 | E7: HNJH2018-002 | F7: 通州公路局 | G7: 张伟 | H7: 13439987630 | I7: 王新星 | J7: 王新星 | K7: 202382 | L7: 45135 | M7: 0 | N7: 202382 | O7: 45135 | P7: 0 | Q7: =N7 -> 202382 | R7: =O7 -> 45135 | S7: =P7 -> 0 | T7: =Q7+R7+S7 -> 247517 | U7: =T7 -> 247517 | V7: 222765.3 | W7: =U7-V7-V8-V9 -> 1.0913936e-11 | X7: =U7*0.8 -> 198013.6 | Y7: =V7*0.8 -> 178212.24 | Z7: =X7-Y7-Y8-Y9 -> 1.4551915e-11 | AA7: 韩国峰 | AB7: 测绘 | AC7: =4.4*2500 -> 11000 | AE7: =20942 -> 20942 | AF7: =X7-AC7-AC8-AC9-AD7-AE7 -> 146837.6 | AH7: =AD7/U7 -> 0 | AI7: =AE7/(Q7*0.8) -> 0.12934698
V8: 24751.7 | Y8: =V8*0.8 -> 19801.36 | AA8: 刘素良 | AB8: 取芯 | AC8: =6*150 -> 900
Y9: =V9*0.8 -> 0 | AA9: 瑞通十九处 | AB9: 路检+弯沉 | AC9: =17.48*800+87*50 -> 18334
D10: 大修，K1111+175-K1115+400 | E10: HNJH2018-002 | F10: 通州公路局 | G10: 张伟 | H10: 13439987630 | I10: 王新星 | J10: 王新星 | K10: 301366.44 | L10: 53182.31 | M10: 0 | N10: =K10*0.99 -> 298352.78 | O10: =L10*0.99 -> 52650.487 | P10: 0 | Q10: 294960.52 | R10: 52051.85 | S10: =P10 -> 0 | T10: =Q10+R10+S10 -> 347012.37 | U10: =T10 -> 347012.37 | V10: 312311.14 | W10: =U10-V10-V11-V12 -> -0.01 | X10: =U10*0.8 -> 277609.9 | Y10: =V10*0.8 -> 249848.91 | Z10: =X10-Y10-Y11-Y12 -> -0.008 | AF10: =X10-AC10-AC11-AC12-AD10-AE10 -> 277609.9 | AH10: =AD10/U10 -> 0 | AI10: =AE10/(Q10*0.8) -> 0
V11: 34701.24 | Y11: =V11*0.8 -> 27760.992
Y12: =V12*0.8 -> 0
A13: 7 | B13: 延庆区京银线、G234、滦赤路、四宝路、北西路大修工程-第四合同段（四宝路）勘察设计---延庆区四宝路（K0+000-K19+300)大修工程 | D13: 大修，19.3km，调整为预养 | E13: HXJH2018-007 | F13: 延庆公路局 | G13: 吴颖 | H13: 13488805779 | I13: 杨建东 | J13: 王新星 | K13: 541919 | L13: 193330 | M13: 0 | N13: =INT(541919*0.99)+1 -> 536500 | O13: =INT(193330*0.99) -> 191396 | P13: 0 | Q13: =N13 -> 536500 | R13: =O13 -> 191396 | S13: =P13 -> 0 | T13: =Q13+R13+S13 -> 727896 | U13: =T13 -> 727896 | W13: =U13-V13-V14-V15 -> 727896 | X13: =U13*0.8 -> 582316.8 | Y13: =V13*0.8 -> 0 | Z13: =X13-Y13-Y14-Y15 -> 582316.8 | AA13: 刘素良 | AB13: 测绘 | AC13: =19.3*2500 -> 48250 | AF13: =X13-AC13-AC14-AC15-AD13-AE13 -> 499202.8 | AH13: =AD13/U13 -> 0 | AI13: =AE13/(Q13*0.8) -> 0
Y14: =V14*0.8 -> 0 | AA14: 刘素良 | AB14: 取芯 | AC14: =16*150 -> 2400
Y15: =V15*0.8 -> 0 | AA15: 十九处 | AB15: 路检 | AC15: =(38.6*800+194*50)*0.8 -> 32464
A16: 13 | B16: 新机场高速公路地下综合管廊（南四环~新机场）工程一期土建施工交通导行工程 | D16: 帮忙刘军达 | E16: HNJH2018-013 | F16: 中铁一局 | G16: 刘军达 | H16: 18518335628 | K16: 31359 | L16: 0 | M16: 0 | N16: 12887.7 | O16: 0 | P16: 0 | Q16: =N16 -> 12887.7 | R16: =O16 -> 0 | S16: =P16 -> 0 | T16: =Q16+R16+S16 -> 12887.7 | U16: =T16 -> 12887.7 | V16: 12887.7 | W16: =U16-V16-V17-V18 -> 0 | X16: =U16*0.8 -> 10310.16 | Y16: =V16*0.8 -> 10310.16 | Z16: =X16-Y16-Y17-Y18 -> 0 | AA16: 刘君达 | AB16: 设计 | AC16: 10310.16 | AF16: =X16-AC16-AC17-AC18-AD16-AE16 -> 1.8189894e-12
Y17: =V17*0.8 -> 0
Y18: =V18*0.8 -> 0
A19: 14 | B19: 2019年通州区台湖镇乡村公路（7条路） | D19: 窑兴路，0.854km | E19: HNJH2018-014L01S | F19: 台湖公路站 | G19: 吕工 | H19: 15801247391 | I19: 王新星 | J19: 王新星 | K19: 145303 | L19: 6807 | M19: 0 | N19: 145303 | O19: 6807 | P19: 0 | Q19: 0 | R19: 0 | S19: =P19 -> 0 | T19: =Q20 -> 139675.75 | U19: =T19 -> 139675.75 | V19: 0 | W19: =U19-V19-V24-V25 -> 139675.75 | X19: =U19*0.8 -> 111740.6 | Y19: =V19*0.8 -> 0 | Z19: =X19-Y19-Y24-Y25 -> 111740.6 | AA19: 刘素良 | AB19: 测绘+取芯 | AC19: =0.854*2000+2*150 -> 2008 | AF19: =X19-AC19-AC20-AC21-AC22-AC23-AC24-AC25-AD19-AE19 -> 92176.6 | AG19: 未施工
D20: 农贸市场路(张台路-铺外四路）K0-K0+920 | E20: HNJH2018-014L07S | K20: 327015 | L20: 27961 | M20: 0 | N20: 327015 | O20: 27961 | P20: 0 | Q20: 139675.75 | R20: 0 | S20: 0 | AA20: 刘素良 | AB20: 测绘 | AC20: =0.92*2000 -> 1840
D21: 政府大街西段 | E21: HNJH2018-014L03S | K21: 314738 | L21: 9439 | M21: 0 | N21: 314738 | O21: 9439 | P21: 0 | Q21: 0 | R21: 0 | S21: 0 | AA21: 刘素良 | AB21: 测绘+取芯 | AC21: =0.62*2000+5*150 -> 1990 | AG21: 未施工
D22: 胡家垡村环路（未出图） | E22: HNJH2018-014L04S | AA22: 刘素良 | AB22: 测绘+取芯 | AC22: =2.24*2000+8*150 -> 5680
D23: 碱厂环路（未出图） | E23: HNJH2018-014L05S | AA23: 刘素良 | AB23: 测绘+取芯 | AC23: =1.149*2000+6*150 -> 3198
D24: 江场村环路（未出图） | E24: HNJH2018-014L06S | AA24: 刘素良 | AB24: 测绘+取芯 | AC24: =0.48*2000+6*150 -> 1860
D25: 北九路（未出图） | E25: HNJH2018-014L02S | AA25: 刘素良 | AB25: 测绘+取芯 | AC25: =1.194*2000+4*150 -> 2988
A26: 15 | B26: 2019年通州区张家湾镇(第三批）乡村公路（6条路） | D26: 枣凤沟路（新建） | E26: HNJH2018-015L01S | F26: 张湾公路站 | G26: 卢世茹 | H26: 13520175981 | I26: 王新星 | J26: 王新星 | K26: 240008.58 | L26: 27871.1 | M26: 0 | N26: 87614.72 | O26: 0 | P26: 0 | Q26: 87614.72 | R26: 0 | S26: =P26 -> 0 | T26: =Q26+Q27+Q28+Q29+Q30+Q31+R26+R27+R28+R29+R30+R31 -> 419201.59 | U26: =T26 -> 419201.59 | V26: 90420 | W26: =U26-V26-V27-V28-V29-V30-V31 -> 0 | X26: =U26*0.8 -> 335361.27 | Y26: =V26*0.8 -> 72336 | Z26: =X26-Y26-Y27-Y28-Y29-Y30-Y31 -> 0 | AA26: 刘素良 | AB26: 测绘+取芯 | AC26: =1.966*2000+6*150 -> 4832 | AD26: =18084+82195.4 -> 100279.4 | AE26: =13953.39+50742.27 -> 64695.66 | AF26: =X26-AC26-AC30-AC31-AD26-AE26 -> 163210.21 | AH26: =AD26/U26 -> 0.23921522 | AI26: =AE26/X26 -> 0.19291333
D27: 何牌路支线（新建） | E27: HNJH2018-015L02S | K27: 146488.99 | L27: 12196 | M27: 0 | N27: 51559.94 | O27: 0 | P27: 0 | Q27: 51559.94 | R27: 0 | S27: =P27 -> 0 | V27: 328781.59 | Y27: =V27*0.8 -> 263025.27 | AA27: 刘素良 | AB27: 测绘+取芯 | AC27: =0.798*2000+0*150 -> 1596
D28: 南姚园生态园路（路网改造） | E28: HNJH2018-015L03S | K28: 137583.32 | L28: 20311.7 | M28: 0 | N28: 45530.91 | O28: 0 | P28: 0 | Q28: 45530.91 | R28: 0 | S28: =P28 -> 0 | AA28: 刘素良 | AB28: 测绘+取芯 | AC28: =1.368*2000+4*150 -> 3336
D29: 东翟路（大修） | E29: HNJH2018-015L04S | K29: 172942.09 | L29: 14513.8 | M29: 0 | N29: 66834.33 | O29: 0 | P29: 0 | Q29: 66834.33 | R29: 0 | S29: =P29 -> 0 | AA29: 刘素良 | AB29: 测绘+取芯 | AC29: =1.071*2000+4*150 -> 2742
D30: 三间房北环路延长线（新建） | E30: HNJH2018-015L05S | K30: 194756.81 | L30: 37680.5 | M30: 0 | N30: 85760.81 | O30: 0 | P30: 0 | Q30: 85760.81 | R30: 0 | S30: =P30 -> 0 | AA30: 刘素良 | AB30: 测绘+取芯 | AC30: =0.824*2000+0*150 -> 1648
D31: 卫生院南路（综合治理） | E31: HNJH2018-015L06S | K31: 242302.45 | L31: 13737.4 | M31: 0 | N31: 81900.88 | O31: 0 | P31: 0 | Q31: 81900.88 | R31: 0 | S31: =P31 -> 0 | AA31: 刘素良 | AB31: 测绘+取芯 | AC31: =0.198*2000+2*150 -> 696
A32: 16 | B32: 房山区河北镇项目-房东路 | D32: 城市次干路2.5km | E32: HNJH2018-016 | F32: 北京圣泉投资有限公司 | G32: 肖建营 | H32: 13911835251 | I32: 杨建东 | J32: 杨建东/王新星 | K32: =3022700+831700 -> 3854400 | L32: 0 | M32: 0 | N32: 3861000 | O32: 0 | P32: 0 | Q32: 3861000 | R32: =O32 -> 0 | S32: =P32 -> 0 | T32: =Q32+R32+S32 -> 3861000 | U32: =T32 -> 3861000 | V32: 1875450 | W32: =U32-V32-V33-V34 -> 1985550 | X32: =U32*0.82 -> 3166020 | Y32: =V32*0.82 -> 1537869 | Z32: =X32-Y32-Y33-Y34 -> 1628151 | AF32: =X32-AC32-AC33-AC34-AD32-AE32 -> 3166020
D33: 桥梁 | Y33: =V33*0.8 -> 0
D34: 给排水 | Y34: =V34*0.8 -> 0
A35: 17 | B35: 通州区2019年公路桥梁改建工程—十仓桥设计 | D35: 位于张家湾镇，8m钢筋混凝土现浇板 | E35: HNJH2018-017 | F35: 通州公路局 | G35: 潘宝龙 | H35: 13439987630 | I35: 王新星 | J35: 王新星 | K35: 121316.91 | L35: 0 | M35: 0 | N35: 59288 | O35: 0 | P35: 0 | Q35: =N35 -> 59288 | R35: =O35 -> 0 | S35: =P35 -> 0 | T35: =Q35+R35+S35 -> 59288 | U35: =T35 -> 59288 | V35: 0 | W35: =U35-V35-V36-V37 -> 59288 | X35: =U35*0.8 -> 47430.4 | Y35: =V35*0.8 -> 0 | Z35: =X35-Y35-Y36-Y37 -> 47430.4 | AF35: =X35-AC35-AC36-AC37-AD35-AE35 -> 47430.4 | AH35: =AD35/U35 -> 0 | AI35: =AE35/(Q35*0.8) -> 0
Y36: =V36*0.8 -> 0
Y37: =V37*0.8 -> 0
A38: 18 | B38: 前苇沟组团棚户区改造土地开发项目平衡资金地块道路工程 | D38: 7条支路,4.87km | E38: ZYJH2018-018 | F38: 北京昆泰嘉恒房地产开发有限公司 | G38: 常工 | H38: 18701639618 | I38: 王新星 | J38: 王新星 | K38: 3526664 | L38: 0 | M38: 0 | N38: 2804700 | O38: 0 | P38: 0 | Q38: =N38 -> 2804700 | R38: =O38 -> 0 | S38: =P38 -> 0 | T38: =Q38+R38+S38 -> 2804700 | U38: =T38 -> 2804700 | V38: 560940 | W38: =U38-V38-V39-V40 -> 841410 | X38: =U38*0.7 -> 1963290 | Y38: =V38*0.7 -> 392658 | Z38: =X38-Y38-Y39-Y40 -> 588987 | AD38: =158011.27 -> 158011.27 | AE38: 55303.94 | AF38: =X38-AC38-AC39-AC40-AD38-AE38 -> 1749974.8 | AH38: =AD38/U38 -> 0.056338029 | AI38: =AE38/X38 -> 0.028169012
V39: 1402350 | Y39: =V39*0.7 -> 981645
Y40: =V40*0.8 -> 0
...

Sheet 2019
A1: 项目经营管理台账（2019年）（电子）
A2: 序号 | B2: 项目信息 | G2: 经营信息 | L2: 概算信息（估算） | O2: 审计信息 | R2: 甲方信息 | Z2: 公司信息 | AJ2: 备注
B3: 项目名称 | C3: 承接 日期 | D3: 项目概况 | E3: 资质 | F3: 项目编号 | G3: 单位 | H3: 联系人 | I3: 联系方式 | J3: 经营 负责人 | K3: 经营 参与人 | L3: 设计费（元） | M3: 勘察费（元） | N3: 可研费（元） | O3: 设计费（元） | P3: 勘察费（元） | Q3: 可研费（元） | R3: 合同/补充协议额（元） | V3: 应支额（元） | W3: 甲方支付信息 | Z3: 应收额（元） | AD3: 公司支付信息 | AI3: 公司结余 （元）
R4: 设计费（元） | S4: 勘察费（元） | T4: 可研费（元） | U4: 补充协议额（元） | W4: 开票金额（元） | X4: 支付金额（元） | Y4: 未收金额（元） | AA4: 开票金额（元） | AB4: 实收金额（元） | AC4: 未收金额（元） | AD4: 单位 （个人） | AE4: 内容 | AF4: 金额（元） | AG4: 经营奖金（元） | AH4: 生产奖金（元）
A5: 1 | B5: 2020年房山区普通公路大修、预防性养护工程勘察设计 | C5: 2019.1.3 | D5: (第1标段西环路）大修+综治（公路，二级，2.831km） | E5: 河南交规院 | F5: HNJH2019-001 | G5: 房山公路局 | H5: 白秀龙 | I5: 13811745176 | J5: 杨建东 | K5: 王新星 | L5: 133940 | M5: 28026 | O5: 193940 | P5: 28026 | R5: =O5 -> 193940 | S5: =P5 -> 28026 | U5: =R5+S5 -> 221966 | V5: =R5+S5 -> 221966 | W5: 133179.6 | X5: 133179.6 | Y5: =V5-X5-X6 -> 0 | Z5: =V5*0.8 -> 177572.8 | AA5: =W5*0.8 -> 106543.68 | AB5: =X5*0.8 -> 106543.68 | AC5: =Z5-AB5-AB6 -> 0 | AD5: 任永超 | AE5: 测绘 | AF5: =3.01*2500 -> 7525 | AG5: 21258.72 | AH5: =15797.72 -> 15797.72 | AI5: =Z5-AG5-AH5 -> 140516.36 | AJ5: 测绘及取芯费用燕山管委会支付，本单位不再另行支付。 | AK5: =AG5/V5 -> 0.095774668 | AL5: =AH5/R5/0.8 -> 0.10182092
W6: 88786.4 | X6: =W6 -> 88786.4 | AA6: =W6*0.8 -> 71029.12 | AB6: =X6*0.8 -> 71029.12 | AD6: 任永超 | AE6: 取芯 | AF6: =13*150 -> 1950
D7: 108国道K42-K67+900 | F7: HNJH2019-001 | L7: 134848 | M7: 259000 | O7: 131768 | P7: 256410 | R7: =O7 -> 131768 | S7: =P7 -> 256410 | U7: =R7+S7 -> 388178 | V7: =U7 -> 388178 | W7: 310542.4 | X7: =W7 -> 310542.4 | Y7: =V7-X7-X8 -> 0 | Z7: =V7*0.8 -> 310542.4 | AA7: =W7*0.8 -> 248433.92 | AB7: 248433.92 | AC7: =Z7-AB7-AB8 -> 0 | AD7: 解远飞 | AE7: 测绘 | AF7: =(67.9-42)*2500 -> 64750 | AG7: =72897.28 -> 72897.28 | AI7: =Z7-AF7-AF8-AG7-AH7 -> 169745.12 | AK7: =AG7/V7 -> 0.18779343 | AL7: =AH7/R7/0.8 -> 0
W8: 77635.6 | X8: 77635.6 | AA8: =W8*0.8 -> 62108.48 | AB8: =AA8 -> 62108.48 | AD8: 刘素良 | AE8: 取芯 | AF8: =21*150 -> 3150
A9: 4 | B9: 通州区2019年健身步道工程 | C9: 2019.1.4 | D9: 儒林小公园位于运河大堤路西侧，健步道全长0.839km | E9: 天津城建院 | F9: CJJH2019-004 | G9: 通州体育局 | H9: 吕海龙 | I9: 13910628276 | J9: 王新星 | K9: 王新星 | L9: 387100 | M9: 101800 | N9: 50000 | O9: 198537.16 | P9: 101800 | Q9: 50000 | R9: =O9 -> 198537.16 | S9: =P9 -> 101800 | T9: 0 | U9: =R9+S9+T9 -> 300337.16 | V9: =U9+U10+U13 -> 350337.16 | W9: =R9+S9+T9 -> 300337.16 | X9: =W9 -> 300337.16 | Y9: =V9-X9-X10-X13 -> 0 | Z9: =V9*0.8-0.01 -> 280269.72 | AA9: 105118 | AB9: =AA9 -> 105118 | AC9: =Z9-AB9-AB10-AB11-AB12 -> -0.0019999999 | AD9: 刘素梁 | AE9: 测绘 | AF9: =0.839*2000 -> 1678 | AG9: =82587.29 -> 82587.29 | AH9: =31765.95+4800+3004.69+12500 -> 52070.64 | AI9: =Z9-AF9-AF11-AG9-AH9 -> 138517.79 | AK9: =AG9/V9 -> 0.2357366 | AL9: =AH9/Z9 -> 0.18578761
R10: =O10 -> 0 | S10: =P10 -> 0 | T10: =Q9 -> 50000 | U10: =R10+S10+T10 -> 50000 | W10: =R10+S10+T10 -> 50000 | X10: =W10 -> 50000 | AA10: 135151.72 | AB10: =AA10 -> 135151.72
D11: 环湖路健步道位于环湖小镇东侧，健步道全长2.708km | AA11: 24000 | AB11: 24000 | AD11: 刘素梁 | AE11: 测绘 | AF11: =2.708*2000 -> 5416
AA12: 16000 | AB12: =AA12 -> 16000
C13: 2019.10.31 | L13: 85200 | M13: 16355.66 | O13: 50946.6 | P13: =M13 -> 16355.66
A14: 6 | B14: 2019年延庆区昌赤路（K53+000-K60+300)中修工程 | C14: 2019.1.14 | D14: 中修（公路二级，7.3km） | E14: 长安大学 | F14: LS2019-31-01 | G14: 延庆公路局 | H14: 刑工 | I14: 13810992745 | J14: 杨建东 | K14: 王新星 | L14: 144356 | M14: 73000 | O14: =L14 -> 144356 | P14: =M14 -> 73000 | R14: =O14 -> 144356 | S14: =P14 -> 73000 | T14: =Q14 -> 0 | U14: =R14+S14+T14 -> 217356 | V14: =U14 -> 217356 | W14: =V14 -> 217356 | X14: =W14 -> 217356 | Y14: =V14-X14 -> 0 | Z14: =V14*0.75-7300 -> 155717 | AA14: 60000 | AB14: 60000 | AC14: =Z14-AB14-AB15 -> 12.25 | AD14: 韩国峰 | AE14: 取芯 | AF14: 2000 | AG14: =U14*0.25 -> 54339 | AH14: =R14*0.75*0.2 -> 21653.4 | AI14: =Z14-AG14-AH14-AF14-AF15 -> 70424.6 | AJ14: 长安，管理费25%，6万元开票，95717元报销。公司收入扣除测量交桩费7300元，差12.25元未给。结清。 | AK14: =AG14/V14 -> 0.25 | AL14: =AH14/R14/0.8 -> 0.1875
AA15: 95704.75 | AB15: =AA15 -> 95704.75 | AD15: 戴工 | AE15: 交桩 | AF15: =7.3*1000 -> 7300
A16: 8 | B16: 2019年延庆区G234（K220+300-K223+650)中修工程 | C16: 2019.1.14 | D16: 中修，公路二级4km | E16: 河北华越 | F16: HNHY2019-008 | G16: 延庆公路局 | H16: 刑工 | I16: 13810992745 | J16: 杨建东 | K16: 王新星 | L16: 180939 | M16: 50250 | O16: =L16 -> 180939 | P16: =M16 -> 50250 | R16: =O16 -> 180939 | S16: =P16 -> 50250 | T16: =Q16 -> 0 | U16: =R16+S16+T16 -> 231189 | V16: =U16 -> 231189 | W16: =V16 -> 231189 | X16: =W16 -> 231189 | Y16: =V16-X16 -> 0 | Z16: =V16*0.82 -> 189574.98 | AA16: 189574.98 | AB16: =AA16 -> 189574.98 | AC16: =Z16-AB16 -> 0 | AD16: 韩国峰 | AE16: 取芯 | AF16: =7*200 -> 1400 | AG16: =U16*0.25 -> 57797.25 | AH16: =29674 -> 29674 | AI16: =Z16-AG16-AH16-AF16-AF17 -> 92328.73 | AJ16: 华越，合同中49544.02.元计入编号18。 | AK16: =AG16/V16 -> 0.25 | AL16: =AH16/R16/0.8 -> 0.20500003
AD17: 韩国峰 | AE17: 测绘 | AF17: =3.35*2500 -> 8375
A18: 12 | B18: 延庆区世园会周边道路标志改造工程 | D18: 公路册一期 | F18: HNHY2019-012 | L18: =30496 -> 30496 | O18: 27814 | R18: =O18 -> 27814 | U18: =R18+S18+T18 -> 27814 | V18: =U18 -> 27814 | W18: =V18 -> 27814 | X18: =W18 -> 27814 | Y18: =V18-X18 -> 0 | Z18: =V18*0.8 -> 22251.2 | AA18: =W18*0.8 -> 22251.2 | AB18: =X18*0.8 -> 22251.2 | AC18: =Z18-AB18 -> 0 | AG18: =6953.5 -> 6953.5 | AH18: =4450.24 -> 4450.24 | AI18: =Z18-AG18-AH18-AF18-AF19 -> 10847.46 | AK18: =AG18/V18 -> 0.25 | AL18: =AH18/R18/0.8 -> 0.2
D19: 公路册二期 | L19: 7747
A20: 13 | B20: 延庆区外石路（K0+395-K5+000)加宽工程 | C20: 2019.3.15 | D20: 外石路两侧加宽，公路三级4.604km | E20: 河南交规院 | F20: HNJH2019-013 | G20: 北京市延庆区八达岭镇人民政府 | H20: 吴颖 | I20: 13488805779 | J20: 杨建东 | K20: 杨建东 | L20: 174890 | O20: 74692.23 | R20: =O20 -> 74692.23 | U20: =R20+S20+T20 -> 74692.23 | V20: =U20 -> 74692.23 | W20: =V20 -> 74692.23 | X20: =W20 -> 74692.23 | Y20: =V20-X20 -> 0 | Z20: =V20*0.8 -> 59753.784 | AA20: 59753.78 | AB20: =Z20 -> 59753.784 | AC20: =Z20-AB20 -> 0 | AG20: =11922.7 -> 11922.7 | AH20: =11221.37 -> 11221.37 | AI20: =Z20-AF20-AG20-AH20 -> 36609.714 | AK20: =AG20/V20 -> 0.15962437 | AL20: =AH20/R20/0.8 -> 0.18779346
A21: 14 | B21: 燕山地区燕东路(北庄路口至丁东路路口)改造提升工程 | C21: 2019.3.22 | D21: 大修，（城市次干路1.957km） | E21: 河南交规院 | F21: HNJH2019-014 | G21: 燕山区办事处 | H21: 穆科长 | I21: 13910416067 | J21: 王新星 | K21: 王新星 | L21: 2379151 | R21: 1673310 | U21: =R21 -> 1673310 | V21: =U21 -> 1673310 | W21: 200000 | X21: =W21 -> 200000 | Y21: =V21-X21-X24-X22-X23 -> 1323310 | Z21: =V21*0.8 -> 1338648 | AA21: =X21*0.8 -> 160000 | AB21: =AA21 -> 160000 | AC21: =Z21-AB21-AB24-AB22-AB23 -> 1058648 | AD21: 张华 | AE21: 效果图 | AF21: =5*160 -> 800 | AI21: =Z21-AF21-AF22-AF23-AG21-AH21-AF24 -> 1337848 | AK21: =AG21/V21 -> 0 | AL21: =AH21/R21/0.8 -> 0
W22: 150000 | X22: 150000 | AA22: 120000 | AB22: 120000
A25: 15 | B25: 2019年通州区台湖镇乡村公路（4条路） | C25: 2019.5.5 | D25: 东水路（乡村路四级2.973km） | E25: 河南交规院 | F25: HNJH2019-015L01S | G25: 台湖公路站 | H25: 吕工 | I25: 15801247391 | J25: 王新星 | K25: 王新星 | L25: 435386.1 | M25: 46849 | O25: 127692.05 | P25: 72490.25 | R25: =O25 -> 127692.05 | S25: =P25 -> 72490.25 | U25: =R25+S25+T25 -> 200182.3 | V25: =U25+U26+U27+U28 -> 408368.96 | W25: 198059 | X25: =W25 -> 198059 | Y25: =V25+V26+V27+V28-X25-X26-X27 -> 81674.96 | Z25: =(V25+V26+V27+V28)*0.8 -> 326695.17 | AA25: =W25*0.8 -> 158447.2 | AB25: =X25*0.8 -> 158447.2 | AC25: =Z25-AB25-AB26 -> 65339.968 | AD25: 任永超 | AE25: 测绘+取芯 | AF25: =2.97*1500+4*150 -> 5055 | AI25: =Z25-AF25-AG25-AH25-AF26-AF27-AF28 -> 319000.17 | AJ25: 西碱路即2017年西下营延长线。已有测图。 | AK25: =AG25/V25 -> 0 | AL25: =AH25/R25/0.8 -> 0
D26: 西碱路（乡村路四级1.282km） | F26: HNJH2019-015L02S | L26: 199589.22 | M26: 15265.51 | O26: 80467.15 | P26: 42466.92 | R26: =O26 -> 80467.15 | S26: =P26 -> 42466.92 | U26: =R26+S26+T26 -> 122934.07 | W26: 128635 | X26: =W26 -> 128635 | AA26: =W26*0.8 -> 102908 | AB26: =X26*0.8 -> 102908 | AD26: 任永超 | AE26: 测绘+取芯 | AF26: 0 | AK26: =AG26/V26 -> #DIV/0! | AL26: =AH26/R26/0.8 -> 0
D27: 台东路（乡村路四级0.81km） | F27: HNJH2019-015L03S | L27: 128666.11 | M27: 21482 | O27: 35765.68 | P27: 21482 | R27: =O27 -> 35765.68 | S27: =P27 -> 21482 | U27: =R27+S27+T27 -> 57247.68 | AD27: 任永超 | AE27: 测绘+取芯 | AF27: =0.814*1500+3*150 -> 1671 | AK27: =AG27/V27 -> #DIV/0! | AL27: =AH27/R27/0.8 -> 0
D28: 台湖西路（乡村路四级0.446km） | F28: HNJH2019-015L05S | L28: 70487.2 | M28: 14482 | O28: 18594.74 | P28: 9410.17 | R28: =O28 -> 18594.74 | S28: =P28 -> 9410.17 | U28: =R28+S28+T28 -> 28004.91 | AD28: 任永超 | AE28: 测绘+取芯 | AF28: =0.446*1500+2*150 -> 969 | AK28: =AG28/V28 -> #DIV/0! | AL28: =AH28/R28/0.8 -> 0
B29: 2019年通州区台湖镇乡村公路（2条路） | D29: 朱家垡西路（乡村路四级0.506km） | F29: HNJH2019-015L04S | L29: 92174.37 | M29: 14475 | O29: 22497.21 | P29: 14475 | R29: =O29 -> 22497.21 | S29: =P29 -> 14475 | U29: =R29+S29+T29 -> 36972.21 | V29: =U29+U30 -> 128712.94 | Y29: =V29-X29-X30 -> 128712.94 | Z29: =V29*0.8 -> 102970.35
D30: 垛子路（乡村路四级1.045km） | F30: HNJH2019-015L06S | L30: 201261.75 | M30: 22698 | O30: 69042.73 | P30: 22698 | R30: =O30 -> 69042.73 | S30: =P30 -> 22698 | U30: =R30+S30+T30 -> 91740.73
A31: 16 | B31: 河北镇棚户区改造临时污水管线工程 | C31: 2019.3.27 | D31: 河北镇污水管线及雨水管线工程 | E31: 天津城建院 | F31: CJJH2019-016 | G31: 河北镇人民政府 | H31: 肖建营 | I31: 13911835251 | J31: 杨建东 | K31: 杨建东 | L31: =28180+171915 -> 200095 | O31: 370681.47 | R31: =O31 -> 370681.47 | U31: =R31+T31+S31 -> 370681.47 | V31: =U31 -> 370681.47 | W31: 146035 | X31: 146035 | Y31: =V31-X31-X32 -> 0 | Z31: =V31*0.8 -> 296545.18 | AA31: 73000 | AB31: 73000 | AC31: =Z31-AB31-AB32 -> 223545.18 | AG31: =18250 -> 18250 | AH31: =14600 -> 14600 | AI31: =Z31-AG31-AH31-AF31-AF32 -> 263695.18 | AJ31: 甲方超支8.25元 | AK31: =AG31/V31 -> 0.049233645 | AL31: =AH31/R31/0.8 -> 0.049233645
W32: =V31-W31 -> 224646.47 | X32: =W32 -> 224646.47
A33: 16‘ | B33: 河北镇棚户区改造临时污水、雨水管线工程竣工图编制 | C33: 2019.3.27 | D33: 河北镇污水管线及雨水管线工程 | E33: 河南交规院 | F33: HNJH2019-016 | G33: 河北镇人民政府 | H33: 肖建营 | I33: 13911835251 | J33: 杨建东 | K33: 杨建东 | L33: 29654.51 | O33: =L33 -> 29654.51 | R33: =O33 -> 29654.51 | U33: =R33+T33+S33 -> 29654.51 | V33: =U33 -> 29654.51 | W33: =U33 -> 29654.51 | X33: =W33 -> 29654.51 | Y33: =V33-X33-X34 -> 0 | Z33: =V33*0.8 -> 23723.608 | AA33: =Z33 -> 23723.608 | AB33: =AA33 -> 23723.608 | AC33: =Z33-AB33-AB34 -> 0 | AG33: =18250 -> 18250 | AH33: =14600 -> 14600 | AI33: =Z33-AG33-AH33-AF33-AF34 -> -9126.392 | AJ33: 甲方超支8.25元 | AK33: =AG33/V33 -> 0.61542072 | AL33: =AH33/R33/0.8 -> 0.61542072
W34: =V33-W33 -> 0 | X34: =W34 -> 0
A35: 17 | B35: 2020年延庆区普通公路大修及桥梁改造工程勘察设计1标段---2020年延庆区G234大修工程(K187+244-K209+113） | C35: 2019.5.15 | D35: 大修，公路一二三级长度29.669km。2020年延庆区G234大修工程(K187+244-K209+113） | E35: 河南交规院 | F35: HNJH2019-017 | G35: 延庆公路局 | H35: 吴颖 | I35: 13488805779 | J35: 杨建东 | K35: 杨建东 | L35: 950607 | M35: 209200 | O35: 949556 | P35: 209200 | R35: 940061 | S35: 175281 | U35: =R35+T35+S35 -> 1115342 | V35: =U35 -> 1115342 | W35: 598308 | X35: =W35 -> 598308 | Y35: =V35-X35-X36-X38-X39-X37 -> 0 | Z35: =V35*0.8 -> 892273.6 | AA35: 478646.4 | AB35: =AA35 -> 478646.4 | AC35: =Z35-AB35-AB36-AB37 -> 413627.2 | AD35: 任永超 | AE35: 测绘 | AF35: =21.869*2500 -> 54672.5 | AG35: =140447.89 -> 140447.89 | AH35: =63553.35 -> 63553.35 | AI35: =Z35-AG35-AH35-AF35-AF36-AF38-AF39-AF37 -> 579554.66 | AK35: =AG35/V35 -> 0.12592361 | AL35: =AH35/R35/0.8 -> 0.08450695
W36: 517034 | X36: =W36 -> 517034 | AD36: 任永超 | AE36: 取芯 | AF36: =11*150 -> 1650
X37: 0 | AD37: 质监站 | AE37: 弯沉盆检测 | AF37: 24000
X38: =W38 -> 0 | AD38: 瑞通十九处 | AE38: 路检 | AF38: =21.869*800 -> 17495.2
X39: =W39 -> 0 | AD39: 瑞通十九处 | AE39: 弯沉 | AF39: =218*50 -> 10900
A40: 18 | B40: 2020年延庆区G234中修工程(209+113-212+400） | C40: 2019.5.24 | D40: 中修，公路二级长度3.287km | E40: 河北华跃 | F40: HNHY2019-018 | G40: 延庆公路局 | H40: 刑工 | I40: 13810992745 | J40: 杨建东 | K40: 杨建东 | L40: 217831 | M40: 51000 | O40: =L40 -> 217831 | P40: =M40 -> 51000 | R40: =O40 -> 217831 | S40: =P40 -> 51000 | T40: =Q40 -> 0 | U40: =R40+T40+S40 -> 268831 | V40: =U40 -> 268831 | W40: 247048 | X40: =W40 -> 247048 | Y40: =V40-X40-X41-X42 -> 0 | Z40: =V40*0.82 -> 220441.42 | AA40: 49544.02 | AB40: =AA40 -> 49544.02 | AC40: =Z40-AB40-AB41-AB42 -> 0.4 | AD40: 任永超 | AE40: 测绘+取芯 | AF40: =3.4*2500+6*150 -> 9400 | AG40: =61762 -> 61762 | AH40: =33462.21 -> 33462.21 | AI40: =Z40-AF40-AF41-AF42-AG40-AH40 -> 115817.21 | AJ40: 华越 | AK40: =AG40/V40 -> 0.22974285 | AL40: =AH40/Z40 -> 0.15179638
W41: 21783 | X41: 21783 | AA41: 156939 | AB41: =AA41 -> 156939
AA42: 13958 | AB42: =AA42 -> 13958
...

Sheet 2020
A1: 项目经营管理台账（2020年）（电子）
A2: 序号 | B2: 项目信息 | G2: 经营信息 | L2: 概算信息（估算） | O2: 审计信息 | R2: 甲方信息 | Z2: 公司信息 | AJ2: 备注
B3: 项目名称 | C3: 承接 日期 | D3: 项目概况 | E3: 资质 | F3: 项目编号 | G3: 单位 | H3: 联系人 | I3: 联系方式 | J3: 经营 负责人 | K3: 经营 参与人 | L3: 设计费（元） | M3: 勘察费（元） | N3: 可研费（元） | O3: 设计费（元） | P3: 勘察费（元） | Q3: 可研费（元） | R3: 合同/补充协议额（元） | V3: 应支额（元） | W3: 甲方支付信息 | Z3: 应收额（元） | AA3: 公司收入信息 | AD3: 公司支付信息 | AI3: 公司结余 （元）
R4: 设计费（元） | S4: 勘察费（元） | T4: 可研费（元） | U4: 补充协议额（元） | W4: 开票金额（元） | X4: 支付金额（元） | Y4: 未收金额（元） | AA4: 开票金额（元） | AB4: 实收金额（元） | AC4: 未收金额（元） | AD4: 单位 （个人） | AE4: 内容 | AF4: 金额（元） | AG4: 经营奖金（元） | AH4: 生产奖金（元）
A5: 1 | B5: 2020年延庆区乡村公路建养工程勘察设计---2标 | C5: 2020.1.10 | D5: 安防一标段 | E5: 河南交规院 | F5: HNJH2020-001 | G5: 北京市交通委员会延庆分局 | H5: 张旭学 | I5: 13811589649 | J5: 杨建东 | K5: 杨建东 | L5: 101006 | O5: 48435 | R5: =O5 -> 48435 | U5: =R5 -> 48435 | V5: =U5+U6 -> 125220 | W5: =U5 -> 48435 | X5: =W5 -> 48435 | Y5: =V5-X5-X6 -> 0 | Z5: =V5*0.8 -> 100176 | AA5: =W5*0.8 -> 38748 | AB5: =AA5 -> 38748 | AC5: =Z5-AB5-AB6 -> 0 | AG5: 12108.75 | AH5: 7749.6 | AI5: =Z5-AF5-AG6-AH65-AF6-AG5-AH5-AH6 -> 48835.8 | AK5: =AG5/R5 -> 0.25 | AL5: =AH5/AB5 -> 0.2
D6: 安防二标段 | L6: 151472 | O6: 76785 | R6: =O6 -> 76785 | U6: =R6 -> 76785 | W6: =U6 -> 76785 | X6: =W6 -> 76785 | AA6: =W6*0.8 -> 61428 | AB6: =AA6 -> 61428 | AG6: 19196.25 | AH6: 12285.6 | AK6: =AG6/R6 -> 0.25 | AL6: =AH6/AB6 -> 0.2
A7: 2 | B7: 通州区体育局2020年健身步道工程 | C7: 2020.1.10 | D7: 6.489公里 | E7: 河南交规院 | F7: HNJH2020-002 | G7: 北京市通州体育局 | H7: 王栋 | I7: 18610277462 | J7: 王新星 | K7: 王新星 | L7: 980573 | M7: 294172 | O7: 575545.53 | P7: 91451.59 | R7: =O7 -> 575545.53 | S7: =P7 -> 91451.59 | U7: =R7+S7 -> 666997.12 | V7: =U7 -> 666997.12 | W7: =V7 -> 666997.12 | X7: =W7 -> 666997.12 | Y7: =V7-X7-X9 -> 0 | Z7: =V7*0.8 -> 533597.7 | AA7: =W7*0.8 -> 533597.7 | AB7: =AA7 -> 533597.7 | AC7: =Z7-AB7 -> 0 | AD7: 任永超 | AE7: 测绘 | AF7: =8.21*1500 -> 12315 | AG7: =156572.1 -> 156572.1 | AH7: =86467 -> 86467 | AI7: =Z7-AG7-AH7-AF7-AF8 -> 277043.6 | AK7: =AG7/V7 -> 0.23474179 | AL7: =AH7/R7/0.8 -> 0.18779357
AD8: 张华 | AE8: 效果图 | AF8: =300*4 -> 1200
A10: 3 | B10: 2020年延庆区普通公路路面、桥梁、隧道中小修工程第3标---隧道 | C10: 2020.1.10 | E10: 河南交规院 | F10: HNJH2020-003 | G10: 北京市交通委员会延庆分局 | H10: 吴颖 | I10: 13488805779 | J10: 杨建东 | K10: 杨建东 | X10: 0 | Y10: =V10-X10-X12 -> 0 | Z10: =V10*0.8 -> 0
X12: 0
A13: 4 | B13: 2020年延庆路网外场设备更新工程 | C13: 2020.3 | D13: 兴阳线、京青线、滦赤路、安四路、妫川路5条道路上更新15套设备，其中更新超声波交调设备8套，可变情报板设备6套，视频监控设备1套，在京青线拆除2套微波交调设备。 | E13: 河南交规院 | F13: HNJH2020-004 | G13: 北京市交通委员会延庆分局 | H13: 于伟 | I13: 13701025230 | J13: 杨建东 | K13: 杨建东 | L13: 82209 | O13: 53949 | R13: =O13 -> 53949 | U13: =R13+S13+T13 -> 53949 | V13: =U13 -> 53949 | W13: =V13 -> 53949 | X13: =W13 -> 53949 | Y13: =V13-X13-X15 -> 0 | Z13: =V13*0.8 -> 43159.2 | AA13: =W13*0.8 -> 43159.2 | AB13: =AA13 -> 43159.2 | AC13: =Z13-AB13 -> 0 | AI13: =Z13-AG13-AH13 -> 43159.2
A16: 5 | B16: 北京市2021年延庆区G234、沈韩路、千小路预防性养护工程2标段勘察设计工程 | C16: 2020.3 | D16: 沈韩路 | E16: 河南交规院 | F16: HNJH2020-005 | G16: 北京市交通委员会延庆分局 | H16: 刑工 | I16: 13810992745 | J16: 杨建东 | K16: 杨建东 | L16: =O16 -> 209490 | M16: =P16 -> 36969 | N16: 0 | O16: 209490 | P16: 36969 | Q16: 0 | R16: =O16-381.75 -> 209108.25 | S16: =P16 -> 36969 | T16: =Q16 -> 0 | U16: =R16+S16+T16 -> 246077.25 | V16: =U16 -> 246077.25 | W16: 225160.59 | X16: 225160.59 | Y16: =V16-X16-X17-X18 -> 3.6379788e-12 | Z16: =V16*0.8 -> 196861.8 | AA16: =W16*0.8 -> 180128.47 | AB16: =X16*0.8 -> 180128.47 | AC16: =Z16-AB16 -> 16733.328 | AD16: 韩国峰 | AE16: 测绘 | AF16: =7*2500 -> 17500
W17: 20916.66 | X17: 20916.66 | AD17: 韩国峰 | AE17: 取芯 | AF17: =8*200 -> 1600
A19: 8 | B19: 燕山地区迎风南路、迎风街路域环境提升工程---燕山政府西环路 | C19: 2020.3 | D19: 慢行系统、景观绿化、公共交通、环境卫生、照明系统提升 | E19: 河南交规院 | F19: HNJH2020-008 | G19: 燕山区办事处 | H19: 穆科长 | I19: 13910416067 | J19: 王新星 | K19: 杨建东 | L19: 1312407 | AD19: 张华 | AE19: 效果图 | AF19: =6*300 -> 1800
A21: 10 | B21: 通州区乡村公路咨询 | C21: 2020.3 | D21: 编制《乡村公路示范路方案咨询报告》 | E21: 北京逸群 | F21: YQJH2020-010 | G21: 北京市交通委员会通州分局 | H21: 张伟 | I21: 13439987630 | J21: 王新星 | K21: 王新星 | N21: 195000 | Q21: 176882 | T21: =U21 -> 176882 | U21: =Q21 -> 176882 | V21: 176882 | W21: =V21 -> 176882 | X21: =W21 -> 176882 | Y21: =V21-X21 -> 0 | Z21: =V21*0.85+0.3 -> 150350 | AA21: =Z21 -> 150350 | AB21: =AA21 -> 150350 | AC21: =Z21-AB21 -> 0 | AD21: 张华 | AE21: 效果图 | AF21: =10*300 -> 3000 | AH21: =28235 -> 28235 | AI21: =Z21-AG21-AH21-AF21 -> 119115
D23: 编制《乡村公路大修工程设计指南》 | N23: 193000 | Q23: 193000 | T23: =Q23 -> 193000 | U23: =T23 -> 193000 | V23: =U23 -> 193000 | W23: =V23 -> 193000 | X23: =W23 -> 193000 | Y23: =V23-X23 -> 0 | Z23: =V23*0.85 -> 164050 | AA23: =Z23 -> 164050 | AB23: =AA23 -> 164050 | AC23: =Z23-AB23 -> 0 | AI23: =Z23-AG23-AH23 -> 164050
A25: 12 | B25: 2020年延庆区妫川路等公路路域环境整治工程 | C25: 2020.4 | E25: 河南交规院 | F25: HNJH2020-012 | G25: 北京市交通委员会延庆分局 | H25: 刑工 | I25: 13810992745 | J25: 杨建东 | K25: 杨建东 | L25: 337094 | M25: 50865 | O25: 331489 | P25: 50865 | R25: =O25 -> 331489 | S25: =P25 -> 50865 | U25: =R25+S25+T25 -> 382354 | V25: =U25 -> 382354 | W25: 349205 | X25: =W25 -> 349205 | Y25: =V25-X25-X26 -> 0 | Z25: =V25*0.8 -> 305883.2 | AA25: 279364 | AB25: =AA25 -> 279364 | AC25: =Z25-AB25-AB26 -> 0 | AD25: 刘素良 | AE25: 测绘 | AF25: =3.2*2500 -> 8000 | AG25: =81973 -> 81973 | AH25: =44821.03 -> 44821.03 | AI25: =Z25-AF25-AF26-AG25-AH25-AG26-AH26 -> 169589.17 | AK25: =AG25/V25 -> 0.21439033 | AL25: =AH25/(R25*0.8) -> 0.16901402
W26: 33149 | X26: 33149 | AA26: =X26*0.8 -> 26519.2 | AB26: =AA26 -> 26519.2 | AD26: 张华 | AE26: 效果图 | AF26: =5*300 -> 1500
A27: 13 | B27: 宁夏回族自治区交通运输综合执法监督局2020年迎国检项目施工图设计 | C27: 2020.7 | D27: 宁夏回族自治区交通运输综合执法监督局2020年迎国检项目对宁夏回族自治区交通运输综合执法监督局所辖银川分局、石嘴山分局、吴忠分局、中卫分局、固原分局下属治超检测站根据实际情况进行部分设施维修更换，包括更换检测车道票亭、检测车道岛头维修粉刷、指示标志标牌维修更换、检测大棚线路维护等；对部分站点进行改造包括：对黄羊滩治超检测站西侧检测车道出入口进行延长拓宽改造；在水洞沟治超检测站增装计重地磅1台；在银巴治超检测站建设3000㎡固定卸载场，卸载场安装静态汽车衡称重复检设备1套；在关马湖治超检测站道口以南新修一条与G344线斜交的货车引道；国道307盐池治超检测站更换计重地磅2台；将S301线石炭井沟口超限检测站搬迁至原S301线石炭井收费站。 | E27: 河南交规院 | F27: HNJH2020-013 | O27: 336000 | U27: 336000 | V27: =U27 -> 336000 | W27: 336000 | X27: =W27 -> 336000 | Y27: =W27-X27 -> 0 | Z27: =V27*0.8 -> 268800 | AA27: =Z27 -> 268800 | AB27: =AA27 -> 268800 | AC27: =Z27-AB27 -> 0 | AD27: 李文博 | AE27: 咨询 | AF27: =V27*0.75 -> 252000 | AG27: 0 | AH27: 0 | AI27: =Z27-AF27 -> 16800
A28: 15 | B28: 2021年房山区普通公路养护工程第3标段：2021年房山区班陈路、紫码路修复养护工程勘察设计 | C28: 2020.4 | D28: 班陈路起点为京昆线，终点陈家台，全长5.583km。K0+000-K0+268、K0+514-K5+583段技术等级为三级公路；K0+268-K0+514段技术等级为二级公路。本次设计段落为班陈路全段。 | E28: 河南交规院 | F28: HNJH2020-015 | G28: 北京市交通委员会房山分局 | H28: 白秀龙 | I28: 13811745176 | J28: 王新星 | K28: 王新星 | L28: 137645 | M28: 45224 | N28: 0 | AD28: 任永超 | AE28: 测绘 | AF28: =5.58*2500 -> 13950
AD29: 任永超 | AE29: 取芯 | AF29: =11*150 -> 1650
AD30: 中交路星 | AE30: 路检 | AF30: =5.583*800 -> 4466.4
D31: 紫码路本次设计段落为K0+000+K4+000，设计长度4km。其中K2+904-K4+000技术等级为三级公路外，其余设计路段为二级公路。 | L31: 184762 | M31: 35608 | N31: 0 | AD31: 任永超 | AE31: 测绘 | AF31: =4.35*2500 -> 10875
AD32: 任永超 | AE32: 取芯 | AF32: =10*150 -> 1500
A34: 16 | B34: 房东路污水管线回填道路恢复工程 | C34: 2020.4 | D34: 路面恢复总面积为3215.4㎡ | E34: 河南交规院 | F34: HNJH2020-016 | G34: 北京市房山区河北镇人民政府 | H34: 肖建营 | I34: 13911835251 | J34: 杨建东 | K34: 杨建东 | L34: 311577.81 | O34: 107181.6 | R34: =O34 -> 107181.6 | U34: =R34+S34+T34 -> 107181.6 | V34: =U34 -> 107181.6 | W34: 107181.6 | X34: =W34 -> 107181.6 | Y34: =V34-X34-X35 -> 0
W35: 0 | X35: 0
A36: 17 | B36: 南海子北环路污水管线工程 | C36: 2020.5 | D36: 污水管线700m | E36: 北京专业院 | F36: ZYJH2020-017 | G36: 北京国苑投资有限公司 | H36: 侯光 | I36: 13910665470 | J36: 王新星 | K36: 王新星 | AJ36: 暂缓
X37: =W37 -> 0
A38: 18 | B38: 2020年通州区台湖镇乡村公路安全生命防护工程 ---台东路、铺外二路、大地路 | C38: 2020.5 | D38: 新建护栏约计890m | E38: 河南交规院 | F38: HNJH2020-018 | G38: 北京市通州区台湖公路管理站 | H38: 李立明 | I38: 13366736778 | J38: 王新星 | K38: 王新星 | X38: =W38 -> 0
O39: 4958.17 | R39: =O39 -> 4958.17 | V39: =R39 -> 4958.17 | W39: 4958.17 | X39: =W39 -> 4958.17 | Y39: =V39-X39 -> 0 | Z39: =V39*0.8 -> 3966.536 | AA39: 3966.54 | AB39: 3966.54 | AC39: =Z39-AB39 -> -0.004
A40: 19 | B40: 2021年通州区普通公路、桥梁养护工程第1标段勘察设计：2021 年通州区柏德路(K3+450-K12+561) 修复养护工程勘察设计 | C40: 2020.6 | D40: 现况道路K3+450-K9+130 段为二级公路，路基横断面为一幅路，路面宽12.5(16)米，路基宽14.5(20)米。K9+130-K12+561 道路等级为三级公路，路基横断面为一幅路，路面宽7.0 米，路基宽9.0 米，全长9.111 公里 | E40: 河南交规院 | F40: HNJH2020-019 | G40: 北京市交通委员会通州分局 | H40: 王晓强 | I40: 13501231567 | J40: 王新星 | K40: 王新星 | L40: 706667 | M40: 84308 | X40: =W40 -> 0 | AD40: 任永超 | AE40: 测绘+取芯 | AF40: =9.111*2500+8*150 -> 23977.5
X41: =W41 -> 0 | AD41: 十九处 | AE41: 弯沉 | AF41: =91*50 -> 4550
X42: =W42 -> 0
A43: 20 | B43: 国网北京房山供电公司电力管线回填 | C43: 2020.6 | D43: 国网北京房山供电公司迎风地区1#开闭站（三供一业）配套外电源改造工程-道路恢复工程 | E43: 河南交规院 | F43: HNJH2020-020 | G43: 国网北京房山供电公司 | H43: 刘睿轩 | I43: 15810458298 | J43: 曹立东 | K43: 王新星 | L43: 504878.95 | R43: 67483.355 | U43: =R43 -> 67483.355 | V43: =U43 -> 67483.355 | W43: =V43 -> 67483.355 | X43: =W43 -> 67483.355 | Y43: =V43-X43 -> 0 | Z43: =V43*0.95-0.86 -> 64108.327 | AA43: =Z43 -> 64108.327 | AB43: =AA43 -> 64108.327 | AC43: =Z43-AB43 -> 0
D44: 国网北京房山供电公司迎风地区2#开闭站（三供一业）配套外电源改造工程--道路恢复工程 | L44: 429369.06 | R44: 57390.518 | U44: =R44 -> 57390.518 | V44: =U44 -> 57390.518 | W44: =V44 -> 57390.518 | X44: =W44 -> 57390.518 | Y44: =V44-X44 -> 0 | Z44: =V44*0.95 -> 54520.992 | AA44: =Z44 -> 54520.992 | AB44: =AA44 -> 54520.992 | AC44: =Z44-AB44 -> 0
D45: 国网北京房山供电公司东风地区2#开闭站（三供一业）配套外电源改造工程--道路恢复工程 | L45: 320008.45 | R45: 42773.112 | U45: =R45 -> 42773.112 | V45: =U45 -> 42773.112 | W45: =V45 -> 42773.112 | X45: =W45 -> 42773.112 | Y45: =V45-X45 -> 0 | Z45: =V45*0.95 -> 40634.456 | AA45: =Z45 -> 40634.456 | AB45: =AA45 -> 40634.456 | AC45: =Z45-AB45 -> 0
D46: 国网北京房山供电公司东风地区1#开闭站（三供一业）配套外电源改造工程--道路恢复工程 | L46: 452979.99 | R46: 60546.413 | U46: =R46 -> 60546.413 | V46: =U46 -> 60546.413 | W46: =V46 -> 60546.413 | X46: =W46 -> 60546.413 | Y46: =V46-X46 -> 0 | Z46: =V46*0.95 -> 57519.092 | AA46: =Z46 -> 57519.092 | AB46: =AA46 -> 57519.092 | AC46: =Z46-AB46 -> 0
D47: 国网北京房山供电公司富燕新村区开闭站（三供一业）配套外电源改造工程--道路恢复工程 | L47: 88832 | R47: 11873.502 | U47: =R47 -> 11873.502 | V47: =U47 -> 11873.502 | W47: =V47 -> 11873.502 | X47: =W47 -> 11873.502 | Y47: =V47-X47 -> 0 | Z47: =V47*0.95 -> 11279.827 | AA47: =Z47 -> 11279.827 | AB47: =AA47 -> 11279.827 | AC47: =Z47-AB47 -> 0
A48: 21 | B48: 房山区G108（K34+300-K42+000）预防性养护工程勘察设计 | C48: 2020.7 | D48: 预养 | E48: 河南交规院 | F48: HNJH2020-021 | G48: 北京市交通委员会房山分局 | H48: 白秀龙 | I48: 13811745176 | J48: 杨建东 | K48: 王新星 | L48: 50292 | M48: 77000 | O48: 50198 | P48: 77000 | R48: =O48 -> 50198 | S48: =P48 -> 77000 | U48: =R48+S48 -> 127198 | V48: =U48 -> 127198 | W48: 101833.6 | X48: =W48 -> 101833.6 | Y48: =V48-X48-X49 -> 0 | Z48: =V48*0.8 -> 101758.4 | AA48: =X48*0.8 -> 81466.88 | AB48: =AA48 -> 81466.88 | AC48: =Z48-AB48-AB49 -> 0 | AG48: =23904.6 -> 23904.6 | AH48: 0 | AI48: =Z48-AG48-AH48 -> 77853.8 | AK48: =AG48/V48 -> 0.1879322 | AL48: =AH48/(R48*0.8) -> 0
W49: 25364.4 | X49: =W49 -> 25364.4 | AA49: =X49*0.8 -> 20291.52 | AB49: =AA49 -> 20291.52
...

Sheet 2021
A1: 项目经营管理台账（2021年）（电子）
A2: 序号 | B2: 项目信息 | G2: 经营信息 | L2: 概算信息（估算） | O2: 审计信息 | R2: 甲方信息 | Y2: 公司信息 | AH2: 备注
B3: 项目名称 | C3: 承接 日期 | D3: 项目概况 | E3: 资质 | F3: 项目编号 | G3: 单位 | H3: 联系人 | I3: 联系方式 | J3: 经营 负责人 | K3: 经营 参与人 | L3: 设计费（元） | M3: 勘察费（元） | N3: 咨询费（元） | O3: 设计费（元） | P3: 勘察费（元） | Q3: 咨询费（元） | R3: 合同/补充协议额（元） | V3: 甲方支付信息 | Y3: 公司收入信息 | AB3: 公司支付信息 | AG3: 公司结余 （元）
R4: 设计费（元） | S4: 勘察费（元） | T4: 咨询费（元） | U4: 合计额（元） | V4: 应支额（元） | W4: 支付金额（元） | X4: 未收金额（元） | Y4: 应收额（元） | Z4: 实收金额（元） | AA4: 未收金额（元） | AB4: 经营奖金（元） | AC4: 生产奖金（元） | AD4: 单位 （个人） | AE4: 内容 | AF4: 金额（元）
A5: 1 | B5: 2021年房山区普通公路养护工程勘察设计（查）设计第1标段---2021年房山区普通公路交通工程勘察设计 | C5: 20221.1.3 | D5: 2021年房山区公路交通安全隐患治理工程 | E5: 河南交规院 | F5: HNJH2021-001 | G5: 北京市交通委员会房山分局 | H5: 王现卫 | I5: 13552275070 | J5: 王新星 | K5: 曹立冬 | L5: 169969 | O5: =L5 -> 169969 | R5: =O5 -> 169969 | U5: =SUM(R5:T7) -> 169969 | V5: =U5 -> 169969 | W5: 144474 | X5: =V5-W5-W6-W7 -> 0 | Y5: =V5*0.8 -> 135975.2 | Z5: =W5*0.8 -> 115579.2 | AA5: =Y5-Z5-Z6-Z7 -> 0 | AD5: 刘素良 | AE5: 测绘 | AF5: =0.2*2500 -> 500 | AG5: =Y5-AB5-AC5-AF5-AF6-AF7 -> 135475.2
W6: 25495 | Z6: =W6*0.8 -> 20396
W7: 0
A8: 2 | B8: 2021年房山区普通公路路面和桥梁中小修工程勘察设计---第1标段—2021年房山区普通公路国省道路面中小修工程勘察设计 | C8: 2021.2. | D8: 2021年普通公路水毁恢复工程 | E8: 河南交规院 | F8: HNJH2021-002 | G8: 北京市交通委员会房山分局 | H8: 王现卫 | I8: 13552275070 | J8: 王新星 | K8: 王新星 | L8: 147220 | O8: 129380 | R8: =O8 -> 129380 | U8: =SUM(R8:T10) -> 129380 | V8: =U8 -> 129380 | W8: 103504 | X8: =V8-W8-W9-W10 -> 0 | Y8: =V8*0.8 -> 103504 | Z8: =W8*0.8 -> 82803.2 | AA8: =Y8-Z8-Z9-Z10 -> 20700.8 | AG8: =Y8-AB8-AC8-AF8-AF9-AF10 -> 103504
W9: 25876
W10: 0
A11: 3 | B11: 星城地区主要道路提升工程 | C11: 2020.2 | D11: 综合治理，城市次干路5.2km | E11: 河南交规院 | F11: HNJH2021-003 | G11: 北京市房山区燕山城市管理和交通委员会 | H11: 穆佳楠 | I11: 13910416067 | J11: 王新星 | K11: 王新星 | R11: 0 | U11: =SUM(R11:T13) -> 0 | V11: =U11 -> 0 | W11: 0 | X11: =V11-W11-W12-W13 -> 0 | Y11: =V11*0.8 -> 0 | AA11: =Y11-Z11-Z12-Z13 -> 0 | AG11: =Y11-AB11-AC11-AF11-AF12-AF13 -> 0
W12: 0
W13: 0
A14: 4 | B14: 2021年延庆区普通公路路面、桥梁、隧道中小修工程勘察设计第1标段：2021年延庆区普通公路路面中小修工程勘察设计 | C14: 2020.3.1 | D14: 东刘路中修工程，4.49km | E14: 河南交规院 | F14: HNJH2021-004 | G14: 北京市交通委员会延庆分局 | H14: 刑工 | I14: 13810992745 | J14: 杨建东 | K14: 杨建东 | L14: 115594 | M14: 20399 | N14: 0 | O14: =134570*0.85 -> 114384.5 | P14: =134570*0.15 -> 20185.5 | Q14: 0 | R14: =O14 -> 114384.5 | S14: =P14 -> 20185.5 | T14: =Q14 -> 0 | U14: =SUM(R14:T15) -> 134570 | V14: =U14 -> 134570 | W14: 123132 | X14: =V14-W14-W15 -> 0 | Y14: =V14*0.8 -> 107656 | Z14: =W14*0.8 -> 98505.6 | AA14: =Y14-Z14-Z15 -> 0 | AD14: 刘素良 | AE14: 测绘 | AF14: =2500*4.49 -> 11225 | AG14: =Y14-AB14-AC14-AF14-AF15 -> 94031 | AH14: 测绘沿用2016年成果
W15: 11438 | Z15: =W15*0.8 -> 9150.4 | AD15: 刘素良 | AE15: 取芯 | AF15: =16*150 -> 2400
D16: 北西路（戴工分包） | O16: 111425 | P16: 0 | Q16: 0 | R16: =O16 -> 111425 | S16: =P16 -> 0 | T16: =Q16 -> 0 | U16: =SUM(R16:T17) -> 111425 | V16: =U16 -> 111425 | W16: 101954 | X16: =V16-W16-W17 -> 0 | Y16: =V16*0.8 -> 89140 | Z16: =W16*0.8 -> 81563.2 | AA16: =Y16-Z16-Z17 -> -1.1823431e-11 | AD16: 戴时云 | AE16: 咨询 | AF16: =V16*0.75 -> 83568.75 | AG16: =Y16-AF16 -> 5571.25 | AH16: 戴工分包
W17: 9471 | Z17: =W17*0.8 -> 7576.8
A18: 5 | B18: 新华家园外电源工程—兴阳线电力管线开挖及回填道路恢复工程 | C18: 2021.3 | D18: 电力管线回填及路面恢复，长890米，面积4490m2 | E18: 河南交规院 | F18: HNJH2021-005 | G18: 新华家园健康科技（北京）有限公司 | J18: 杨建东 | K18: 杨建东 | L18: 159887 | M18: 0 | N18: 0 | O18: =L18 -> 159887 | P18: 0 | Q18: 0 | R18: =O18 -> 159887 | S18: 0 | T18: 0 | U18: =SUM(R18:T20) -> 159887 | V18: =U18 -> 159887 | W18: 143898.3 | X18: =V18-W18-W19 -> 0 | Y18: =V18*0.8 -> 127909.6 | Z18: =W18*0.8 -> 115118.64 | AA18: =Y18-Z18-Z19-Z20 -> 5.4569682e-12 | AB18: =22969.68 -> 22969.68 | AC18: 21618.52 | AG18: =Y18-AB18-AC18-AF18-AF19-AF20 -> 83321.4 | AI18: =AB18/V18 -> 0.14366196 | AJ18: =AC18/R18/0.8 -> 0.16901405
W19: 15988.7 | Z19: =W19*0.8 -> 12790.96
W20: 0 | Z20: =W20*0.8 -> 0
A21: 6 | B21: 改善办学条件-基础设施改造-校园道路及附属设施改造工程（设计） | C21: 2021.4 | E21: 河南交规院 | F21: HNJH2021-006 | G21: 北京农业职业学院 | H21: 盖振华 | J21: 王新星 | K21: 王新星 | L21: 349996.52 | O21: 320000 | R21: =O21 -> 320000 | U21: =SUM(R21:T23) -> 320000 | V21: =U21 -> 320000 | W21: 96000 | X21: =V21-W21-W22-W23 -> 0 | Y21: =V21*0.8 -> 256000 | Z21: =W21*0.8 -> 76800 | AA21: =Y21-Z21-Z22-Z23 -> 0 | AB21: =45971.83+54028.17 -> 100000 | AC21: =38460.09+48075.12*0.2 -> 48075.114 | AD21: 专家费 | AF21: 2800 | AG21: =Y21-AB21-AC21-AF21-AF22-AF23 -> 98824.886 | AI21: =AB21/V21 -> 0.3125 | AJ21: =AC21/R21/0.8 -> 0.18779341
W22: 192000 | Z22: =W22*0.8 -> 153600 | AD22: 代理服务费 | AF22: 4800
W23: 32000 | Z23: =W23*0.8 -> 25600 | AD23: 招标文件 | AF23: 1500
A24: 7 | B24: 2021年延庆区标线覆划工程 | C24: 2021.7 | E24: 河南交规院 | F24: HNJH2021-007 | G24: 北京市交通委员会延庆分局 | H24: 刘一圻 | I24: 15210239334 | J24: 杨建东 | K24: 杨建东 | L24: 70488 | O24: =R24 -> 69783 | R24: =6978+62805 -> 69783 | U24: =SUM(R24:T25) -> 69783 | V24: =U24 -> 69783 | W24: 62805 | X24: =V24-W24-W25 -> 0 | Y24: =V24*0.8 -> 55826.4 | Z24: =W24*0.8 -> 50244 | AA24: =Y24-Z24-Z25 -> 0 | AG24: =Y24-AB24-AC24-AF24-AF25 -> 55826.4
W25: 6978 | Z25: =W25*0.8 -> 5582.4
A26: 8 | B26: 京雄高速跨路交通导行工程//、京雄高速跨路恢复工程（同上合并） | C26: 2021.7 | D26: 3工区（走瑞通）（走京宏） | E26: 河南交规院 | F26: HNJH2021-008-1 | G26: 京雄高速项目经理部 | H26: 闫超 | I26: 13811311956 | J26: 曹立冬 | K26: 曹立冬 | L26: 124586.5 | O26: =L26 -> 124586.5 | R26: =O26 -> 124586.5 | U26: =SUM(R26:T28) -> 124586.5 | V26: =U26 -> 124586.5 | W26: 0 | X26: =V26-W26-W27-W28 -> 124586.5 | Y26: =V26 -> 124586.5 | AA26: =Y26-Z26-Z27-Z28 -> 124586.5 | AG26: =Y26-AB26-AC26-AF26-AF27-AF28 -> 124586.5
W27: 0
W28: 0
C29: 2021.7 | D29: 4工区（走河南交规院），长于路支线永久导改工程 | E29: 河南交规院 | F29: HNJH2021-008-2 | J29: 曹立冬 | K29: 曹立冬 | L29: 70785 | O29: =L29 -> 70785 | R29: 70785 | U29: =SUM(R29:T31) -> 70785 | V29: =U29 -> 70785 | W29: 0 | X29: =V29-W29-W30-W31 -> 70785 | Y29: =V29*0.8 -> 56628 | AA29: =Y29-Z29-Z30-Z31 -> 56628 | AG29: =Y29-AB29-AC29-AF29-AF30-AF31 -> 56628
W30: 0
W31: 0
C32: 2021.7 | D32: 4工区（走河南交规院），长阳路导改 | E32: 河南交规院 | F32: HNJH2021-008-2 | H32: 张哲 | I32: 15533018887 | J32: 曹立冬 | K32: 曹立冬 | L32: 24136.7 | O32: 24136.7 | R32: 24136.7 | U32: =SUM(R32:T34) -> 24136.7 | V32: =U32 -> 24136.7 | W32: 0 | X32: =V32-W32-W33-W34 -> 24136.7 | Y32: =V32*0.8 -> 19309.36 | AA32: =Y32-Z32-Z33-Z34 -> 19309.36 | AG32: =Y32-AB32-AC32-AF32-AF33-AF34 -> 19309.36
W33: 0
W34: 0
C35: 2021.7 | D35: 6工区（走瑞通）（走京宏） | E35: 河南交规院 | F35: HNJH2021-008-3 | J35: 曹立冬 | K35: 曹立冬 | L35: 162660.48 | R35: 0 | U35: =SUM(R35:T37) -> 0 | V35: =U35 -> 0 | W35: 0 | X35: =V35-W35-W36-W37 -> 0 | Y35: =V35*0.8 -> 0 | AA35: =Y35-Z35-Z36-Z37 -> 0 | AG35: =Y35-AB35-AC35-AF35-AF36-AF37 -> 0
W36: 0
W37: 0
C38: 2021.7 | D38: 7工区（走京宏） | E38: 河南交规院 | F38: HNJH2021-008-4 | J38: 曹立冬 | K38: 曹立冬 | L38: 54382 | O38: =L38 -> 54382 | R38: 54382 | U38: =SUM(R38:T40) -> 54382 | V38: =U38 -> 54382 | W38: 54382 | X38: =V38-W38-W39-W40 -> 0 | Y38: =U38 -> 54382 | Z38: =Y38 -> 54382 | AA38: =Y38-Z38-Z39-Z40 -> 0 | AG38: =Y38-AB38-AC38-AF38-AF39-AF40 -> 54382
W39: 0 | Z39: 0
W40: 0 | Z40: 0
...

Sheet 2022
A1: 项目经营管理台账（2022年）（电子）
A2: 序号 | B2: 项目信息 | G2: 经营信息 | L2: 概算信息（估算） | O2: 审计信息 | R2: 甲方信息 | Y2: 公司信息 | AH2: 备注
B3: 项目名称 | C3: 承接 日期 | D3: 项目概况 | E3: 资质 | F3: 项目编号 | G3: 单位 | H3: 联系人 | I3: 联系方式 | J3: 经营 负责人 | K3: 经营 参与人 | L3: 设计费（元） | M3: 勘察费（元） | N3: 咨询费（元） | O3: 设计费（元） | P3: 勘察费（元） | Q3: 咨询费（元） | R3: 合同/补充协议额（元） | V3: 甲方支付信息 | Y3: 公司收入信息 | AB3: 公司支付信息 | AG3: 公司结余 （元）
R4: 设计费（元） | S4: 勘察费（元） | T4: 咨询费（元） | U4: 合计额（元） | V4: 应支额（元） | W4: 支付金额（元） | X4: 未收金额（元） | Y4: 应收额（元） | Z4: 实收金额（元） | AA4: 未收金额（元） | AB4: 经营奖金（元） | AC4: 生产奖金（元） | AD4: 单位 （个人） | AE4: 内容 | AF4: 金额（元）
A5: 1 | B5: 2022年重大义务植树活动南火垡植树区域内道路修复工程 | C5: 2022.3 | E5: 河南交规院 | F5: HNJH2022-001 | G5: 张湾公路站 | H5: 卢世茹 | I5: 13520175981 | J5: 王新星 | K5: 王新星 | L5: 13090.26 | O5: 13090.26 | R5: 13090.26 | U5: =SUM(R5:T7) -> 13090.26 | V5: =U5 -> 13090.26 | W5: 13090.26 | X5: =V5-W5-W6-W7 -> 0 | Y5: =V5*0.8 -> 10472.208 | AA5: =Y5-Z5-Z6-Z7 -> 10472.208 | AG5: =Y5-AB5-AC5-AF5-AF6-AF7 -> 10472.208
W6: 0
W7: 0
A8: 2 | B8: 2022年大兴区普通公路中修、桥梁中修、小修维护及应急抢险工程、绿化工程和交通工程勘察设计第4标段 | C8: 2022.4 | E8: 河南交规院 | F8: HNJH2022-002 | G8: 北京市交通委员会大兴分局 | H8: 解鹏 | I8: 13381203969 | J8: 王新星 | K8: 王新星 | R8: 0 | U8: =SUM(R8:T10) -> 0 | V8: =U8 -> 0 | W8: 0 | X8: =V8-W8-W9-W10 -> 0 | Y8: =V8*0.8 -> 0 | AA8: =Y8-Z8-Z9-Z10 -> 0 | AG8: =Y8-AB8-AC8-AF8-AF9-AF10 -> 0
W9: 0
W10: 0
A11: 3 | B11: 2022年延庆区普通公路路面、桥梁、隧道中修工程、小修维护及应急抢险工程、绿化工程、交通工程勘察设计第1标段 | C11: 2022.4 | D11: 永艾路，5.733km，6m | E11: 河南交规院 | F11: HNJH2022-003-01 | G11: 北京市交通委员会延庆分局 | H11: 刑工 | I11: 13810992745 | J11: 杨建东 | K11: 杨建东 | O11: 134649 | P11: 23761 | R11: =O11 -> 134649 | S11: =P11 -> 23761 | U11: =R11+S11 -> 158410 | V11: =U11 -> 158410 | W11: 144945 | X11: =V11-W11-W12 -> 0 | Y11: =V11*0.8 -> 126728 | AA11: =Y11-Z11-Z13-Z22 -> -1645.6 | AD11: 任永超 | AE11: 测绘 | AF11: =5.733*2500 -> 14332.5 | AG11: =Y11-AB11-AC11-AF11-AF12 -> 110595.5
W12: 13465 | AD12: 任永超 | AE12: 取芯 | AF12: =12*150 -> 1800
D13: 千小路，6km，6m | F13: HNJH2022-003-02 | O13: 149068 | P13: 26306 | R13: =O13 -> 149068 | S13: =P13 -> 26306 | U13: =R13+S13 -> 175374 | V13: =U13 -> 175374 | W13: 160467 | X13: =V13-W13-W14 -> 14907 | Y13: =U13*0.8 -> 140299.2 | Z13: =W13*0.8 -> 128373.6 | AA13: =Y13-Z13-Z14 -> 11925.6 | AD13: 任永超 | AE13: 取芯 | AF13: =7*150 -> 1050 | AG13: =Y13-AB13-AC13-AF13-AF14 -> 139249.2
D15: 付小路边沟修复工程，200米 | F15: HNJH2022-003-03 | O15: =37685+3501 -> 41186 | R15: =O15 -> 41186 | U15: =R15+S15 -> 41186 | V15: =U15 -> 41186 | W15: 37685 | X15: =V15-W15-W16 -> 0 | Y15: 0 | AA15: 0 | AG15: =Y15-AB15-AC15-AF15-AF16 -> 0
W16: 3501
D17: 2022年延庆区普通公路挡墙恢复项目-2022年延庆区普通公路日常养护-滦赤路、兴阳线挡墙恢复项目 | F17: HNJH2022-003-04 | O17: 77193 | P17: 13622 | R17: =O17 -> 77193 | S17: =P17 -> 13622 | U17: =R17+S17 -> 90815 | V17: =U17 -> 90815 | W17: 83096 | X17: =V17-W17-W18 -> 0 | Y17: 0 | AA17: 0 | AG17: =Y17-AB17-AC17-AF17-AF18 -> 0
W18: 7719
D19: 祁付路，1.969km | F19: HNJH2022-003-05 | O19: 78637 | P19: 13877 | R19: =O19 -> 78637 | S19: =P19 -> 13877 | U19: =R19+S19 -> 92514 | V19: =U19 -> 92514 | W19: 84650 | X19: =V19-W19-W20 -> 7864 | Y19: =U19*0.8 -> 74011.2 | Z19: =W19*0.8 -> 67720 | AA19: =Y19-Z19-Z20 -> 6291.2 | AD19: 任永超 | AE19: 测绘 | AF19: =1.839*2500 -> 4597.5 | AG19: =Y19-AB19-AC19-AF19-AF20 -> 68813.7
AD20: 任永超 | AE20: 取芯 | AF20: =4*150 -> 600
D21: 东岔路，3km | F21: HNJH2022-003-06 | O21: 121724 | P21: 21481 | R21: =O21 -> 121724 | S21: =P21 -> 21481 | U21: =R21+S21 -> 143205 | V21: =U21 -> 143205 | W21: 131033 | X21: =V21-W21-W22 -> 12172 | Y21: =U21*0.8 -> 114564 | Z21: =W21*0.8 -> 104826.4 | AA21: =Y21-Z21-Z22 -> 9737.6 | AD21: 任永超 | AE21: 测绘 | AF21: =2.04*2500 -> 5100 | AG21: =Y21-AB21-AC21-AF21-AF22 -> 108714
AD22: 任永超 | AE22: 取芯 | AF22: =5*150 -> 750
A23: 4 | B23: 房山区西潞街道东沿村集体土地租赁住房项目市政工程（工程设计、地形测绘） | C23: 2022.4 | E23: 河南交规院 | F23: HNJH2022-004 | H23: 王伟 | I23: 13801288357 | J23: 王新星 | K23: 王新星 | L23: 261666.77 | M23: 0 | N23: 0 | O23: 0 | P23: 0 | Q23: 0 | R23: =O23 -> 0 | S23: =P23 -> 0 | T23: =Q23 -> 0 | U23: =SUM(R23:T24) -> 0 | V23: =U23 -> 0 | W23: 0 | X23: =V23-W23-W24 -> 0 | Y23: =V23*0.8 -> 0 | Z23: =W23*0.8 -> 0 | AA23: =Y23-Z23-Z24 -> 0 | AD23: 任永超 | AE23: 测绘、物探 | AF23: 8000 | AG23: =Y23-AB23-AC23-AF23-AF24 -> -8000
W24: 0 | Z24: =W24*0.8 -> 0
W25: 0 | Z25: =W25*0.8 -> 0
A26: 5 | B26: 2021年延庆区城东一次供热管网改造工程—妫川路（庆园街-庆隆街）热力管线回填道路恢复工程 | C26: 2022.6 | D26: 城市主干路管线掘路回填338米 | E26: 河南交规院 | F26: HNJH2022-005 | G26: 北京市交通委员会延庆分局 | H26: 刑工 | I26: 13810992745 | J26: 杨建东 | K26: 杨建东 | L26: 27452.02 | M26: 0 | N26: 0 | O26: 91506.74 | P26: 0 | Q26: 0 | R26: =O26 -> 91506.74 | S26: 0 | T26: 0 | U26: =SUM(R26:T28) -> 91506.74 | V26: =U26 -> 91506.74 | W26: 27452.02 | X26: =V26-W26-W27-W28 -> 64054.72 | Y26: =V26*0.8 -> 73205.392 | Z26: =W26*0.8 -> 21961.616 | AA26: =Y26-Z26-Z27-Z28 -> 51243.776 | AG26: =Y26-AB26-AC26-AF26-AF27-AF28 -> 73205.392
W27: 0 | Z27: =W27*0.8 -> 0
W28: 0 | Z28: =W28*0.8 -> 0
A29: 6 | B29: 第2标段：大兴区国道106交通综合治理工程勘察设计 | C29: 2022.8 | D29: 长度600米 | E29: 河南交规院 | F29: HNJH2022-006 | G29: 北京市交通委员会大兴分局 | H29: 陈友来 | J29: 王新星 | K29: 王新星 | L29: =261666.77*0.85 -> 222416.75 | M29: =261666.77*0.15 -> 39250.015 | N29: 0 | O29: =L29 -> 222416.75 | P29: =M29 -> 39250.015 | Q29: 0 | R29: 222416.75 | S29: 39250.02 | T29: 0 | U29: =SUM(R29:T31) -> 261666.77 | V29: =U29 -> 261666.77 | W29: 235500 | X29: =V29-W29-W30-W31 -> -1.0913936e-11 | Y29: =V29*0.8 -> 209333.42 | Z29: =W29*0.8 -> 188400 | AA29: =Y29-Z29-Z30-Z31 -> -3.6379788e-12 | AD29: 刘素良 | AE29: 测绘 | AF29: =0.85*2500 -> 2125 | AG29: =Y29-AB29-AC29-AF29-AF30-AF31 -> 207208.42
W30: 26166.77 | Z30: =W30*0.8 -> 20933.416
W31: 0 | Z31: =W31*0.8 -> 0
A32: 7 | B32: 第2标段琉陶路（K0+000-K11+319）修复养护工程勘察设计 | C32: 2022.8 | D32: 公路三级，长度11.139公里 | E32: 华西 | F32: HXJH2022-007 | G32: 北京市交通委员会房山分局 | H32: 刘然 | J32: 王新星 | K32: 王新星 | L32: =529899-M32 -> 419899 | M32: =11*10000 -> 110000 | N32: 0 | O32: =L32 -> 419899 | P32: =M32 -> 110000 | Q32: 0 | R32: =INT(O32*0.99) -> 415700 | S32: =INT(P32*0.99) -> 108900 | T32: 1 | U32: =SUM(R32:T34) -> 524601 | V32: =U32 -> 524601 | W32: 0 | X32: =V32-W32-W33-W34 -> 524601 | Y32: =V32*0.81 -> 424926.81 | Z32: =W32*0.8 -> 0 | AA32: =Y32-Z32-Z33-Z34 -> 424926.81 | AD32: 任永超 | AE32: 测绘 | AF32: =11.319*2500 -> 28297.5 | AG32: =Y32-AB32-AC32-AF32-AF33-AF34 -> 396629.31
W33: 0 | Z33: =W33*0.8 -> 0
W34: 0 | Z34: =W34*0.8 -> 0
A35: 8 | B35: 第4标段G108（K34+300-K68+000）修复养护工程勘察设计 | C35: 2022.8 | D35: 公路二级，长度34公里 | E35: 河南交规院 | F35: HNJH2022-008 | G35: 北京市交通委员会房山分局 | H35: 刘然 | J35: 王新星 | K35: 王新星 | L35: =838410-M35 -> 498410 | M35: =10000*34 -> 340000 | N35: 0 | O35: =L35 -> 498410 | P35: =M35 -> 340000 | Q35: =N35 -> 0 | R35: =INT(O35*0.99) -> 493425 | S35: =INT(P35*0.99) -> 336600 | T35: =INT(Q35*0.99) -> 0 | U35: =SUM(R35:T37) -> 830025 | V35: =U35 -> 830025 | W35: 0 | X35: =V35-W35-W36-W37 -> 830025 | Y35: =V35*0.8 -> 664020 | AA35: =Y35-Z35-Z36-Z37 -> 664020 | AD35: 刘素良 | AE35: 测绘 | AF35: =7.8*2500 -> 19500 | AG35: =Y35-AB35-AC35-AF35-AF36-AF37 -> 644520
W36: 0
W37: 0
A38: 9 | B38: 107 国道临时开口工程设计 | C38: 2022.9 | E38: 河南交规院 | F38: HNJH2022-009 | G38: 中铁五局 | J38: 曹立东 | K38: 曹立东 | L38: 50000 | O38: 50000 | R38: 50000 | U38: =SUM(R38:T40) -> 50000 | V38: =U38 -> 50000 | W38: 10000 | X38: =V38-W38-W39-W40 -> 0 | Y38: =V38*0.8 -> 40000 | Z38: =W38*0.8 -> 8000 | AA38: =Y38-Z38-Z39-Z40 -> 0 | AG38: =Y38-AB38-AC38-AF38-AF39-AF40 -> 40000
W39: 40000 | Z39: =W39*0.8 -> 32000
W40: 0
A41: 总计 | L41: =SUM(L5:L40) -> 1492934.8 | M41: =SUM(M5:M40) -> 489250.02 | N41: =SUM(N5:N40) -> 0 | O41: =SUM(O5:O40) -> 1897779.8 | P41: =SUM(P5:P40) -> 588297.02 | Q41: =SUM(Q5:Q40) -> 0 | R41: =SUM(R5:R40) -> 1888595.8 | S41: =SUM(S5:S40) -> 583797.02 | ... AB41: =SUM(AB5:AB40) -> 0 | AC41: =SUM(AC5:AC7) -> 0 | AF41: =SUM(AF5:AF40) -> 86152.5 | AG41: =SUM(AG5:AG7) -> 10472.208
...

Sheet 2023  
A1: 项目经营管理台账（2023年）（电子）
A2: 序号 | B2: 项目信息 | G2: 经营信息 | I2: 概算信息（估算） | L2: 审计信息 | O2: 合同、支付信息 | V2: 收入、分包支付信息 | AI2: 备注
B3: 项目名称 | C3: 承接 日期 | D3: 项目概况 | E3: 资质 | F3: 项目编号 | G3: 单位 | H3: 联系人 | I3: 设计费（元） | J3: 勘察费（元） | K3: 咨询费（元） | L3: 设计费（元） | M3: 勘察费（元） | N3: 咨询费（元） | O3: 合同/补充协议额（元） | S3: 甲方支付信息 | V3: 公司收入信息 | Y3: 公司支付信息 | AH3: 公司结余 （元）
O4: 设计费（元） | P4: 勘察费（元） | Q4: 咨询费（元） | R4: 合计额（元） | S4: 应支额（元） | T4: 支付金额（元） | U4: 未收金额（元） | V4: 应收额（元） | W4: 实收金额（元） | X4: 未收金额（元） | Y4: 应发经营奖金（元） | Z4: 扣减经营奖金（元） | AA4: 实发经营奖金（元） | AB4: 应发生产奖金（元） | AC4: 扣减生产奖金（元） | AD4: 实发生产奖金（元） | AE4: 单位 （个人） | AF4: 内容 | AG4: 金额（元）
